Workbook

Sheet داده خام
A1: شماره پذیرش | B1: ماه | C1: کد ماه | D1: نوع محصول | E1: مدل | F1: شماره سریال | G1: اظهار مشتری | H1: شرح خرابی | I1: تاریخ پذیرش | J1: تاریخ تولید | K1: تاریخ نصب | L1: مدت مصرف (ماه) | M1: دسته علت خرابی | N1: قطعه تعویضی | O1: مراجعه تکراری | P1: یک سریال دو تاریخ پذیرش
A2: 100004312 | B2: شهریور | C2: 1405-06 | D2: یخچال مینی | E2: CM-RM5ST1 | F2: 52240020N00054 | G2: کسري قطعات پک بسته بندي - کد قطعه در ليست اقدامات درج مي گردد.**اياب و ذهاب به عهده شرکت | H2: کسري قطعات تزئيني داخل درب - يخچال ميني | I2: 1405/06/04 | J2: 1405/03/27 | L2: =IF(OR(TRIM(I2)="",TRIM(K2)=""),"",IFERROR((VALUE(LEFT(TRIM(I2),4))-VALUE(LEFT(TRIM(K2),4)))*12+VALUE(MID(TRIM(I2),6,2))-VALUE(MID(TRIM(K2),6,2)),"")) | M2: =IF(TRIM(H2)="","",IFERROR(LOOKUP(2,1/(ISNUMBER(SEARCH('منطق دسته‌بندی'!$A$2:$A$187,H2))),'منطق دسته‌بندی'!$B$2:$B$187),"سایر (نیازمند بررسی دستی)")) -> قطعات تزئینی - شکستگی/کسری (تعویض) | N2: MINI جا تخم مرغی | O2: {=IF(A2="","",IF(SUMPRODUCT(($B$2:$B$965=B2)*($C$2:$C$965=C2)*($D$2:$D$965=D2)*($E$2:$E$965=E2)*($F$2:$F$965=F2)*($G$2:$G$965=G2)*($H$2:$H$965=H2)*($I$2:$I$965=I2)*($J$2:$J$965=J2)*($K$2:$K$965=K2)*($N$2:$N$965=N2))=1,"خیر",IF(SUMPRODUCT(($B$2:B2=B2)*($C$2:C2=C2)*($D$2:D2=D2)*($E$2:E2=E2)*($F$2:F2=F2)*($G$2:G2=G2)*($H$2:H2=H2)*($I$2:I2=I2)*($J$2:J2=J2)*($K$2:K2=K2)*($N$2:N2=N2))=1,"بله-1","بله")))} -> خیر | P2: {=IF(A2="","",IF(SUMPRODUCT(($F$2:$F$969=F2)*($I$2:$I$969=I2))=1,"خیر",IF(SUMPRODUCT(($F$2:F2=F2)*($I$2:I2=I2))=1,"بله-1","بله")))} -> خیر
A3: 310006211 | B3: شهریور | C3: 1405-06 | D3: یخچال مینی | E3: CM-RS5WH1 | F3: 52240010N00042 | G3: خاموش و روشن شدن LED کاور / سقفي ** اياب و ذهاب به عهده شرکت | H3: خرابی LED | I3: 1405/06/01 | J3: 1405/03/10 | K3: 1405/04/22 | L3: =IF(OR(TRIM(I3)="",TRIM(K3)=""),"",IFERROR((VALUE(LEFT(TRIM(I3),4))-VALUE(LEFT(TRIM(K3),4)))*12+VALUE(MID(TRIM(I3),6,2))-VALUE(MID(TRIM(K3),6,2)),"")) -> 2 | M3: =IF(TRIM(H3)="","",IFERROR(LOOKUP(2,1/(ISNUMBER(SEARCH('منطق دسته‌بندی'!$A$2:$A$187,H3))),'منطق دسته‌بندی'!$B$2:$B$187),"سایر (نیازمند بررسی دستی)")) -> خرابی - لامپ/LED داخلی (تعویض) | N3: MINI LED یخچال | O3: {=IF(A3="","",IF(SUMPRODUCT(($B$2:$B$965=B3)*($C$2:$C$965=C3)*($D$2:$D$965=D3)*($E$2:$E$965=E3)*($F$2:$F$965=F3)*($G$2:$G$965=G3)*($H$2:$H$965=H3)*($I$2:$I$965=I3)*($J$2:$J$965=J3)*($K$2:$K$965=K3)*($N$2:$N$965=N3))=1,"خیر",IF(SUMPRODUCT(($B$2:B3=B3)*($C$2:C3=C3)*($D$2:D3=D3)*($E$2:E3=E3)*($F$2:F3=F3)*($G$2:G3=G3)*($H$2:H3=H3)*($I$2:I3=I3)*($J$2:J3=J3)*($K$2:K3=K3)*($N$2:N3=N3))=1,"بله-1","بله")))} -> خیر | P3: {=IF(A3="","",IF(SUMPRODUCT(($F$2:$F$969=F3)*($I$2:$I$969=I3))=1,"خیر",IF(SUMPRODUCT(($F$2:F3=F3)*($I$2:I3=I3))=1,"بله-1","بله")))} -> خیر
A4: 210019559 | B4: مرداد | C4: 1405-05 | D4: یخچال مینی | E4: CM-RM5WH1 | F4: 52240009N00273 | G4: ایاب و ذهاب به عهده شرکت — بسته نشدن درب | H4: خرابی کلید فشاری | I4: 1405/05/19 | J4: 1405/04/31 | L4: =IF(OR(TRIM(I4)="",TRIM(K4)=""),"",IFERROR((VALUE(LEFT(TRIM(I4),4))-VALUE(LEFT(TRIM(K4),4)))*12+VALUE(MID(TRIM(I4),6,2))-VALUE(MID(TRIM(K4),6,2)),"")) | M4: =IF(TRIM(H4)="","",IFERROR(LOOKUP(2,1/(ISNUMBER(SEARCH('منطق دسته‌بندی'!$A$2:$A$187,H4))),'منطق دسته‌بندی'!$B$2:$B$187),"سایر (نیازمند بررسی دستی)")) -> کلید فشاری (تعویض/بازبینی) | N4: MINI کلید فشاری یخچال | O4: {=IF(A4="","",IF(SUMPRODUCT(($B$2:$B$965=B4)*($C$2:$C$965=C4)*($D$2:$D$965=D4)*($E$2:$E$965=E4)*($F$2:$F$965=F4)*($G$2:$G$965=G4)*($H$2:$H$965=H4)*($I$2:$I$965=I4)*($J$2:$J$965=J4)*($K$2:$K$965=K4)*($N$2:$N$965=N4))=1,"خیر",IF(SUMPRODUCT(($B$2:B4=B4)*($C$2:C4=C4)*($D$2:D4=D4)*($E$2:E4=E4)*($F$2:F4=F4)*($G$2:G4=G4)*($H$2:H4=H4)*($I$2:I4=I4)*($J$2:J4=J4)*($K$2:K4=K4)*($N$2:N4=N4))=1,"بله-1","بله")))} -> خیر | P4: {=IF(A4="","",IF(SUMPRODUCT(($F$2:$F$969=F4)*($I$2:$I$969=I4))=1,"خیر",IF(SUMPRODUCT(($F$2:F4=F4)*($I$2:I4=I4))=1,"بله-1","بله")))} -> خیر
A5: 210023216 | B5: شهریور | C5: 1405-06 | D5: یخچال مینی | E5: CM-RM5WH1 | F5: 52240009N00267 | G5: گرم شدن محصول**اياب و ذهاب به عهده شرکت | H5: اصلاح سوکت کمپرسور | I5: 1405/06/12 | J5: 1405/05/01 | L5: =IF(OR(TRIM(I5)="",TRIM(K5)=""),"",IFERROR((VALUE(LEFT(TRIM(I5),4))-VALUE(LEFT(TRIM(K5),4)))*12+VALUE(MID(TRIM(I5),6,2))-VALUE(MID(TRIM(K5),6,2)),"")) | M5: =IF(TRIM(H5)="","",IFERROR(LOOKUP(2,1/(ISNUMBER(SEARCH('منطق دسته‌بندی'!$A$2:$A$187,H5))),'منطق دسته‌بندی'!$B$2:$B$187),"سایر (نیازمند بررسی دستی)")) -> سیم‌کشی/اتصالات (تعمیر/تنظیم) | N5: --- | O5: {=IF(A5="","",IF(SUMPRODUCT(($B$2:$B$965=B5)*($C$2:$C$965=C5)*($D$2:$D$965=D5)*($E$2:$E$965=E5)*($F$2:$F$965=F5)*($G$2:$G$965=G5)*($H$2:$H$965=H5)*($I$2:$I$965=I5)*($J$2:$J$965=J5)*($K$2:$K$965=K5)*($N$2:$N$965=N5))=1,"خیر",IF(SUMPRODUCT(($B$2:B5=B5)*($C$2:C5=C5)*($D$2:D5=D5)*($E$2:E5=E5)*($F$2:F5=F5)*($G$2:G5=G5)*($H$2:H5=H5)*($I$2:I5=I5)*($J$2:J5=J5)*($K$2:K5=K5)*($N$2:N5=N5))=1,"بله-1","بله")))} -> خیر | P5: {=IF(A5="","",IF(SUMPRODUCT(($F$2:$F$969=F5)*($I$2:$I$969=I5))=1,"خیر",IF(SUMPRODUCT(($F$2:F5=F5)*($I$2:I5=I5))=1,"بله-1","بله")))} -> خیر
A6: 210021319 | B6: شهریور | C6: 1405-06 | D6: یخچال مینی | E6: CM-RM5WH1 | F6: 52240009N00225 | G6: گرم شدن محصول**اياب و ذهاب به عهده شرکت | H6: تنظیم ترموستات | I6: 1405/06/01 | J6: 1405/04/31 | L6: =IF(OR(TRIM(I6)="",TRIM(K6)=""),"",IFERROR((VALUE(LEFT(TRIM(I6),4))-VALUE(LEFT(TRIM(K6),4)))*12+VALUE(MID(TRIM(I6),6,2))-VALUE(MID(TRIM(K6),6,2)),"")) | M6: =IF(TRIM(H6)="","",IFERROR(LOOKUP(2,1/(ISNUMBER(SEARCH('منطق دسته‌بندی'!$A$2:$A$187,H6))),'منطق دسته‌بندی'!$B$2:$B$187),"سایر (نیازمند بررسی دستی)")) -> تنظیم ترموستات (تعمیر/تنظیم) | N6: --- | O6: {=IF(A6="","",IF(SUMPRODUCT(($B$2:$B$965=B6)*($C$2:$C$965=C6)*($D$2:$D$965=D6)*($E$2:$E$965=E6)*($F$2:$F$965=F6)*($G$2:$G$965=G6)*($H$2:$H$965=H6)*($I$2:$I$965=I6)*($J$2:$J$965=J6)*($K$2:$K$965=K6)*($N$2:$N$965=N6))=1,"خیر",IF(SUMPRODUCT(($B$2:B6=B6)*($C$2:C6=C6)*($D$2:D6=D6)*($E$2:E6=E6)*($F$2:F6=F6)*($G$2:G6=G6)*($H$2:H6=H6)*($I$2:I6=I6)*($J$2:J6=J6)*($K$2:K6=K6)*($N$2:N6=N6))=1,"بله-1","بله")))} -> خیر | P6: {=IF(A6="","",IF(SUMPRODUCT(($F$2:$F$969=F6)*($I$2:$I$969=I6))=1,"خیر",IF(SUMPRODUCT(($F$2:F6=F6)*($I$2:I6=I6))=1,"بله-1","بله")))} -> خیر
A7: 130010154 | B7: مرداد | C7: 1405-05 | D7: یخچال مینی | E7: CM-RS5GR1 | F7: 52240006N00731 | G7: رنگ پريدگي درب**اياب و ذهاب به عهده شرکت | H7: رنگ پریدگی درب | I7: 1405/05/26 | J7: 1405/02/02 | L7: =IF(OR(TRIM(I7)="",TRIM(K7)=""),"",IFERROR((VALUE(LEFT(TRIM(I7),4))-VALUE(LEFT(TRIM(K7),4)))*12+VALUE(MID(TRIM(I7),6,2))-VALUE(MID(TRIM(K7),6,2)),"")) | M7: =IF(TRIM(H7)="","",IFERROR(LOOKUP(2,1/(ISNUMBER(SEARCH('منطق دسته‌بندی'!$A$2:$A$187,H7))),'منطق دسته‌بندی'!$B$2:$B$187),"سایر (نیازمند بررسی دستی)")) -> بدنه/درب - ایراد ظاهری (بازبینی) | N7: تعویض محصول | O7: {=IF(A7="","",IF(SUMPRODUCT(($B$2:$B$965=B7)*($C$2:$C$965=C7)*($D$2:$D$965=D7)*($E$2:$E$965=E7)*($F$2:$F$965=F7)*($G$2:$G$965=G7)*($H$2:$H$965=H7)*($I$2:$I$965=I7)*($J$2:$J$965=J7)*($K$2:$K$965=K7)*($N$2:$N$965=N7))=1,"خیر",IF(SUMPRODUCT(($B$2:B7=B7)*($C$2:C7=C7)*($D$2:D7=D7)*($E$2:E7=E7)*($F$2:F7=F7)*($G$2:G7=G7)*($H$2:H7=H7)*($I$2:I7=I7)*($J$2:J7=J7)*($K$2:K7=K7)*($N$2:N7=N7))=1,"بله-1","بله")))} -> خیر | P7: {=IF(A7="","",IF(SUMPRODUCT(($F$2:$F$969=F7)*($I$2:$I$969=I7))=1,"خیر",IF(SUMPRODUCT(($F$2:F7=F7)*($I$2:I7=I7))=1,"بله-1","بله")))} -> خیر
A8: 510024753 | B8: شهریور | C8: 1405-06 | D8: یخچال مینی | E8: CM-RS5GR1 | F8: 52240006N00670 | G8: خاموش بودن LED کاور / سقفي**شکستگي قطعات تزئيني کابين- کد قطعه در ليست اقدامات درج مي گردد.**اياب و ذهاب به عهده شرکت | H8: خرابی LED | I8: 1405/06/01 | J8: 1404/12/09 | L8: =IF(OR(TRIM(I8)="",TRIM(K8)=""),"",IFERROR((VALUE(LEFT(TRIM(I8),4))-VALUE(LEFT(TRIM(K8),4)))*12+VALUE(MID(TRIM(I8),6,2))-VALUE(MID(TRIM(K8),6,2)),"")) | M8: =IF(TRIM(H8)="","",IFERROR(LOOKUP(2,1/(ISNUMBER(SEARCH('منطق دسته‌بندی'!$A$2:$A$187,H8))),'منطق دسته‌بندی'!$B$2:$B$187),"سایر (نیازمند بررسی دستی)")) -> خرابی - لامپ/LED داخلی (تعویض) | N8: MINI LED یخچال | O8: {=IF(A8="","",IF(SUMPRODUCT(($B$2:$B$965=B8)*($C$2:$C$965=C8)*($D$2:$D$965=D8)*($E$2:$E$965=E8)*($F$2:$F$965=F8)*($G$2:$G$965=G8)*($H$2:$H$965=H8)*($I$2:$I$965=I8)*($J$2:$J$965=J8)*($K$2:$K$965=K8)*($N$2:$N$965=N8))=1,"خیر",IF(SUMPRODUCT(($B$2:B8=B8)*($C$2:C8=C8)*($D$2:D8=D8)*($E$2:E8=E8)*($F$2:F8=F8)*($G$2:G8=G8)*($H$2:H8=H8)*($I$2:I8=I8)*($J$2:J8=J8)*($K$2:K8=K8)*($N$2:N8=N8))=1,"بله-1","بله")))} -> خیر | P8: {=IF(A8="","",IF(SUMPRODUCT(($F$2:$F$969=F8)*($I$2:$I$969=I8))=1,"خیر",IF(SUMPRODUCT(($F$2:F8=F8)*($I$2:I8=I8))=1,"بله-1","بله")))} -> خیر
A9: 210024158 | B9: شهریور | C9: 1405-06 | D9: یخچال مینی | E9: CM-RS5GR1 | F9: 52240006N00362 | G9: شکستگي قطعات تزئيني درب- کد قطعه در ليست اقدامات درج مي گردد. ** خاموش و روشن شدن LED آبسردکن ** اياب و ذهاب به عهده شرکت | H9: شکستگي قطعات تزئيني داخل درب - يخچال ميني | I9: 1405/06/17 | J9: 1404/11/08 | K9: 1405/03/04 | L9: =IF(OR(TRIM(I9)="",TRIM(K9)=""),"",IFERROR((VALUE(LEFT(TRIM(I9),4))-VALUE(LEFT(TRIM(K9),4)))*12+VALUE(MID(TRIM(I9),6,2))-VALUE(MID(TRIM(K9),6,2)),"")) -> 3 | M9: =IF(TRIM(H9)="","",IFERROR(LOOKUP(2,1/(ISNUMBER(SEARCH('منطق دسته‌بندی'!$A$2:$A$187,H9))),'منطق دسته‌بندی'!$B$2:$B$187),"سایر (نیازمند بررسی دستی)")) -> قطعات تزئینی - شکستگی/کسری (تعویض) | N9: MINI شلف کوچک یخچال | O9: {=IF(A9="","",IF(SUMPRODUCT(($B$2:$B$965=B9)*($C$2:$C$965=C9)*($D$2:$D$965=D9)*($E$2:$E$965=E9)*($F$2:$F$965=F9)*($G$2:$G$965=G9)*($H$2:$H$965=H9)*($I$2:$I$965=I9)*($J$2:$J$965=J9)*($K$2:$K$965=K9)*($N$2:$N$965=N9))=1,"خیر",IF(SUMPRODUCT(($B$2:B9=B9)*($C$2:C9=C9)*($D$2:D9=D9)*($E$2:E9=E9)*($F$2:F9=F9)*($G$2:G9=G9)*($H$2:H9=H9)*($I$2:I9=I9)*($J$2:J9=J9)*($K$2:K9=K9)*($N$2:N9=N9))=1,"بله-1","بله")))} -> خیر | P9: {=IF(A9="","",IF(SUMPRODUCT(($F$2:$F$969=F9)*($I$2:$I$969=I9))=1,"خیر",IF(SUMPRODUCT(($F$2:F9=F9)*($I$2:I9=I9))=1,"بله-1","بله")))} -> خیر
A10: 130011968 | B10: شهریور | C10: 1405-06 | D10: يخچال ميني | E10: MINI-R | F10: 52240005N00190 | G10: خاموش و روشن شدن LED کاور / سقفي**اياب و ذهاب به عهده شرکت | H10: خرابی LED | I10: 1405/06/23 | J10: 1404/06/29 | K10: 1404/09/24 | L10: =IF(OR(TRIM(I10)="",TRIM(K10)=""),"",IFERROR((VALUE(LEFT(TRIM(I10),4))-VALUE(LEFT(TRIM(K10),4)))*12+VALUE(MID(TRIM(I10),6,2))-VALUE(MID(TRIM(K10),6,2)),"")) -> 9 | M10: =IF(OR(ISNUMBER(SEARCH("بدون مورد",H10)),ISNUMBER(SEARCH("غير گارانتي",H10)),ISNUMBER(SEARCH("غیر گارانتی",H10)),ISNUMBER(SEARCH("بدون اجرت",H10)),ISNUMBER(SEARCH("فيلتر",H10)),ISNUMBER(SEARCH("فیلتر",H10))),"غیرگارانتی/بدون قطعه",IF(OR(ISNUMBER(SEARCH("ريست",H10)),ISNUMBER(SEARCH("ریست",H10))),"ریست نرم‌افزاری (بدون قطعه)",IF(OR(ISNUMBER(SEARCH("تعویض محصول",H10)),ISNUMBER(SEARCH("تعویض دستگاه",H10))),"تعویض کامل دستگاه (Replacement)",IF(ISNUMBER(SEARCH("پمپ",H10)),IF(ISNUMBER(SEARCH("نشت",H10)),"نشتی - پمپ تخلیه (تعمیر/آب‌بندی)","خرابی - پمپ تخلیه (تعویض)"),IF(ISNUMBER(SEARCH("کمپرسور",H10)),"خرابی - کمپرسور (تعویض)",IF(ISNUMBER(SEARCH("کمک فنر",H10)),"خرابی - کمک فنر (تعویض)",IF(ISNUMBER(SEARCH("لولا",H10)),"مکانیزم درب - لولا (تعویض)",IF(OR(ISNUMBER(SEARCH("قلاب",H10)),ISNUMBER(SEARCH("ميکروسوئيچ",H10)),ISNUMBER(SEARCH("میکروسوئیچ",H10))),"مکانیزم درب - میکروسوئیچ/قلاب (تعویض/تنظیم)",IF(ISNUMBER(SEARCH("زبانه",H10)),"مکانیزم درب - زبانه (تعویض)",IF(OR(ISNUMBER(SEARCH("شيلنگ",H10)),ISNUMBER(SEARCH("شیلنگ",H10))),IF(OR(ISNUMBER(SEARCH("نشتی",H10)),ISNUMBER(SEARCH("نشتي",H10))),"نشتی - شیلنگ (تعمیر/آب‌بندی)",IF(OR(ISNUMBER(SEARCH("يخ",H10)),ISNUMBER(SEARCH("یخ",H10))),"شیلنگ یخساز - یخ‌زدگی (بازبینی)","شیلنگ - برخورد/لهیدگی (بازبینی)")),IF(OR(ISNUMBER(SEARCH("تنظيم ديسپل",H10)),ISNUMBER(SEARCH("تنظیم دیسپل",H10)),ISNUMBER(SEARCH("تنظيم صفحه نمايش",H10)),ISNUMBER(SEARCH("تنظیم صفحه نمایش",H10))),"تنظیم - تنظیمات دستگاه/دیسپلی (تعمیر)",IF(OR(ISNUMBER(SEARCH("برد",H10)),ISNUMBER(SEARCH("سوکت",H10)),ISNUMBER(SEARCH("ديسپل",H10)),ISNUMBER(SEARCH("دیسپل",H10))),"خرابی - برد الکترونیک (تعویض)",IF(OR(ISNUMBER(SEARCH("يخساز",H10)),ISNUMBER(SEARCH("یخساز",H10)),ISNUMBER(SEARCH("دمپر",H10))),IF(OR(ISNUMBER(SEARCH("خرابی",H10)),ISNUMBER(SEARCH("خراب",H10)),ISNUMBER(SEARCH("عدم کارکرد",H10)),ISNUMBER(SEARCH("عدم عملکرد",H10))),"یخساز - خرابی موتور/سنسور/برد (تعویض)","یخساز - تنظیم/عایق (تعمیر)"),IF(OR(ISNUMBER(SEARCH("لاستيک",H10)),ISNUMBER(SEARCH("لاستیک",H10))),"لاستیک درزگیر - دفرمگی/پارگی (تعویض)",IF(OR(ISNUMBER(SEARCH("گسکت",H10)),ISNUMBER(SEARCH("گسگت",H10))),"لاستیک درزگیر - دفرمگی/پارگی (تعویض)",IF(ISNUMBER(SEARCH("مخزن نمک",H10)),"نشتی - درب مخزن نمک (تعمیر/آب‌بندی)",IF(ISNUMBER(SEARCH("براکت",H10)),"نشتی - براکت ریل (تعمیر/آب‌بندی)",IF(ISNUMBER(SEARCH("جاپودر",H10)),"نشتی - جاپودری (تعمیر/آب‌بندی)",IF(ISNUMBER(SEARCH("مقسم",H10)),"نشتی - مقسم آب (تعمیر/آب‌بندی)",IF(OR(ISNUMBER(SEARCH("سنسور دما",H10)),ISNUMBER(SEARCH("ترموستات",H10))),"خرابی - ترموستات (تعویض)",IF(OR(ISNUMBER(SEARCH("هيدروستات",H10)),ISNUMBER(SEARCH("هیدروستات",H10))),"خرابی - هیدروستات (تعویض)",IF(OR(ISNUMBER(SEARCH("بلبرينگ",H10)),ISNUMBER(SEARCH("بلبرینگ",H10))),"خرابی - بلبرینگ (تعویض)",IF(OR(ISNUMBER(SEARCH("شيربرق",H10)),ISNUMBER(SEARCH("شیربرق",H10))),"خرابی - شیربرقی (تعویض)",IF(OR(ISNUMBER(SEARCH("واتر جت",H10)),ISNUMBER(SEARCH("واترجت",H10))),"خرابی - واترجت (تعویض)",IF(OR(ISNUMBER(SEARCH("سيم",H10)),ISNUMBER(SEARCH("سیم",H10)),ISNUMBER(SEARCH("اتصال",H10))),"سیم‌کشی/اتصالات (تعویض/بازبینی)",IF(OR(ISNUMBER(SEARCH("تصوير",H10)),ISNUMBER(SEARCH("تصویر",H10))),"برد نمایش تلویزیون (تعویض)",IF(OR(ISNUMBER(SEARCH("ريموت",H10)),ISNUMBER(SEARCH("ریموت",H10))),"ریموت کنترل (تعویض/تعمیر)",IF(OR(ISNUMBER(SEARCH("ال اي دي",H10)),ISNUMBER(SEARCH("ال ای دی",H10)),ISNUMBER(SEARCH("LED",H10))),"خرابی - لامپ/LED داخلی (تعویض)",IF(ISNUMBER(SEARCH("زنگ زدگ",H10)),"زنگ‌زدگی بدنه/قطعه (تعویض)",IF(OR(ISNUMBER(SEARCH("قطعات تزئين",H10)),ISNUMBER(SEARCH("قطعات تزئین",H10))),"قطعات تزئینی - شکستگی/کسری (تعویض)",IF(ISNUMBER(SEARCH("سبد",H10)),"سبد ظرفشویی - شکستگی (تعویض)",IF(ISNUMBER(SEARCH("تاب درام",H10)),"خرابی - تاب برداشتن درام (تعویض)",IF(ISNUMBER(SEARCH("درام",H10)),"خرابی - سایر ایراد درام (تعویض)",IF(ISNUMBER(SEARCH("موتور",H10)),"خرابی - موتور (تعویض)",IF(ISNUMBER(SEARCH("تسمه",H10)),"خرابی - تسمه (تعویض)",IF(OR(ISNUMBER(SEARCH("پيچ ولوم",H10)),ISNUMBER(SEARCH("پیچ ولوم",H10))),"تنظیم - پیچ ولوم/دکمه (تعمیر)",IF(OR(ISNUMBER(SEARCH("کسري قطعات",H10)),ISNUMBER(SEARCH("کسری قطعات",H10))),"کسری قطعات تزئینی (تعویض)",IF(ISNUMBER(SEARCH("پرچ",H10)),"پرچ/بدنه کابین(تعمیر)",IF(OR(ISNUMBER(SEARCH("نشت",H10)),ISNUMBER(SEARCH("آبريزش",H10)),ISNUMBER(SEARCH("آبریزش",H10))),"نشتی آب - محل نامشخص (نیازمند بازدید)",IF(ISNUMBER(SEARCH("درب",H10)),"سایر اجزای درب (بازبینی)",IF(ISNUMBER(SEARCH("ضربه",H10)),"بدنه/کابین - ضربه (بازبینی/تعویض پنل)",IF(ISNUMBER(SEARCH("تراز",H10)),"تراز/لرزش - نصب (رگلاژ پایه)",IF(OR(ISNUMBER(SEARCH("تعویض",H10)),ISNUMBER(SEARCH("تعويض",H10))),"تعویض کامل دستگاه (Replacement)","سایر (نیازمند بررسی دستی)"))))))))))))))))))))))))))))))))))))))))))) -> خرابی - لامپ/LED داخلی (تعویض) | N10: MINI LED یخچال | O10: {=IF(A10="","",IF(SUMPRODUCT(($B$2:$B$965=B10)*($C$2:$C$965=C10)*($D$2:$D$965=D10)*($E$2:$E$965=E10)*($F$2:$F$965=F10)*($G$2:$G$965=G10)*($H$2:$H$965=H10)*($I$2:$I$965=I10)*($J$2:$J$965=J10)*($K$2:$K$965=K10)*($N$2:$N$965=N10))=1,"خیر",IF(SUMPRODUCT(($B$2:B10=B10)*($C$2:C10=C10)*($D$2:D10=D10)*($E$2:E10=E10)*($F$2:F10=F10)*($G$2:G10=G10)*($H$2:H10=H10)*($I$2:I10=I10)*($J$2:J10=J10)*($K$2:K10=K10)*($N$2:N10=N10))=1,"بله-1","بله")))} -> خیر | P10: {=IF(A10="","",IF(SUMPRODUCT(($F$2:$F$969=F10)*($I$2:$I$969=I10))=1,"خیر",IF(SUMPRODUCT(($F$2:F10=F10)*($I$2:I10=I10))=1,"بله-1","بله")))} -> خیر
A11: 210017131 | B11: مرداد | C11: 1405-05 | D11: یخچال مینی | E11: CM-RS5BL1 | F11: 52240005N00063 | G11: خاموش بودن LED کاور / سقفی — ایاب و ذهاب به عهده مشتری | H11: خرابی LED | I11: 1405/05/04 | K11: 1404/08/04 | L11: =IF(OR(TRIM(I11)="",TRIM(K11)=""),"",IFERROR((VALUE(LEFT(TRIM(I11),4))-VALUE(LEFT(TRIM(K11),4)))*12+VALUE(MID(TRIM(I11),6,2))-VALUE(MID(TRIM(K11),6,2)),"")) -> 9 | M11: =IF(TRIM(H11)="","",IFERROR(LOOKUP(2,1/(ISNUMBER(SEARCH('منطق دسته‌بندی'!$A$2:$A$187,H11))),'منطق دسته‌بندی'!$B$2:$B$187),"سایر (نیازمند بررسی دستی)")) -> خرابی - لامپ/LED داخلی (تعویض) | N11: MINI LED یخچال | O11: {=IF(A11="","",IF(SUMPRODUCT(($B$2:$B$965=B11)*($C$2:$C$965=C11)*($D$2:$D$965=D11)*($E$2:$E$965=E11)*($F$2:$F$965=F11)*($G$2:$G$965=G11)*($H$2:$H$965=H11)*($I$2:$I$965=I11)*($J$2:$J$965=J11)*($K$2:$K$965=K11)*($N$2:$N$965=N11))=1,"خیر",IF(SUMPRODUCT(($B$2:B11=B11)*($C$2:C11=C11)*($D$2:D11=D11)*($E$2:E11=E11)*($F$2:F11=F11)*($G$2:G11=G11)*($H$2:H11=H11)*($I$2:I11=I11)*($J$2:J11=J11)*($K$2:K11=K11)*($N$2:N11=N11))=1,"بله-1","بله")))} -> خیر | P11: {=IF(A11="","",IF(SUMPRODUCT(($F$2:$F$969=F11)*($I$2:$I$969=I11))=1,"خیر",IF(SUMPRODUCT(($F$2:F11=F11)*($I$2:I11=I11))=1,"بله-1","بله")))} -> خیر
A12: 210018440 | B12: مرداد | C12: 1405-05 | D12: یخچال مینی | E12: CM-RS5BL1 | F12: 52240005N00063 | G12: خاموش بودن LED کاور / سقفی — مجدد — ایاب و ذهاب به عهده شرکت | H12: خرابی LED | I12: 1405/05/12 | J12: 1404/04/22 | K12: 1404/08/04 | L12: =IF(OR(TRIM(I12)="",TRIM(K12)=""),"",IFERROR((VALUE(LEFT(TRIM(I12),4))-VALUE(LEFT(TRIM(K12),4)))*12+VALUE(MID(TRIM(I12),6,2))-VALUE(MID(TRIM(K12),6,2)),"")) -> 9 | M12: =IF(TRIM(H12)="","",IFERROR(LOOKUP(2,1/(ISNUMBER(SEARCH('منطق دسته‌بندی'!$A$2:$A$187,H12))),'منطق دسته‌بندی'!$B$2:$B$187),"سایر (نیازمند بررسی دستی)")) -> خرابی - لامپ/LED داخلی (تعویض) | N12: MINI LED یخچال | O12: {=IF(A12="","",IF(SUMPRODUCT(($B$2:$B$965=B12)*($C$2:$C$965=C12)*($D$2:$D$965=D12)*($E$2:$E$965=E12)*($F$2:$F$965=F12)*($G$2:$G$965=G12)*($H$2:$H$965=H12)*($I$2:$I$965=I12)*($J$2:$J$965=J12)*($K$2:$K$965=K12)*($N$2:$N$965=N12))=1,"خیر",IF(SUMPRODUCT(($B$2:B12=B12)*($C$2:C12=C12)*($D$2:D12=D12)*($E$2:E12=E12)*($F$2:F12=F12)*($G$2:G12=G12)*($H$2:H12=H12)*($I$2:I12=I12)*($J$2:J12=J12)*($K$2:K12=K12)*($N$2:N12=N12))=1,"بله-1","بله")))} -> خیر | P12: {=IF(A12="","",IF(SUMPRODUCT(($F$2:$F$969=F12)*($I$2:$I$969=I12))=1,"خیر",IF(SUMPRODUCT(($F$2:F12=F12)*($I$2:I12=I12))=1,"بله-1","بله")))} -> خیر
A13: 310007859 | B13: مرداد | C13: 1405-05 | D13: یخچال مینی | E13: CM-RS5BK2 | F13: 52240004N00484 | G13: خاموش و روشن شدن LED کاور / سقفی — ایاب و ذهاب به عهده شرکت | H13: خرابی کلید فشاری | I13: 1405/05/17 | J13: 1404/11/01 | K13: 1405/04/01 | L13: =IF(OR(TRIM(I13)="",TRIM(K13)=""),"",IFERROR((VALUE(LEFT(TRIM(I13),4))-VALUE(LEFT(TRIM(K13),4)))*12+VALUE(MID(TRIM(I13),6,2))-VALUE(MID(TRIM(K13),6,2)),"")) -> 1 | M13: =IF(TRIM(H13)="","",IFERROR(LOOKUP(2,1/(ISNUMBER(SEARCH('منطق دسته‌بندی'!$A$2:$A$187,H13))),'منطق دسته‌بندی'!$B$2:$B$187),"سایر (نیازمند بررسی دستی)")) -> کلید فشاری (تعویض/بازبینی) | N13: MINI کلید فشاری یخچال | O13: {=IF(A13="","",IF(SUMPRODUCT(($B$2:$B$965=B13)*($C$2:$C$965=C13)*($D$2:$D$965=D13)*($E$2:$E$965=E13)*($F$2:$F$965=F13)*($G$2:$G$965=G13)*($H$2:$H$965=H13)*($I$2:$I$965=I13)*($J$2:$J$965=J13)*($K$2:$K$965=K13)*($N$2:$N$965=N13))=1,"خیر",IF(SUMPRODUCT(($B$2:B13=B13)*($C$2:C13=C13)*($D$2:D13=D13)*($E$2:E13=E13)*($F$2:F13=F13)*($G$2:G13=G13)*($H$2:H13=H13)*($I$2:I13=I13)*($J$2:J13=J13)*($K$2:K13=K13)*($N$2:N13=N13))=1,"بله-1","بله")))} -> خیر | P13: {=IF(A13="","",IF(SUMPRODUCT(($F$2:$F$969=F13)*($I$2:$I$969=I13))=1,"خیر",IF(SUMPRODUCT(($F$2:F13=F13)*($I$2:I13=I13))=1,"بله-1","بله")))} -> خیر
A14: 510025638 | B14: شهریور | C14: 1405-06 | D14: یخچال مینی | E14: CM-RS5BK2 | F14: 52240004N00400 | G14: خاموش بودن LED کاور / سقفي**اياب و ذهاب به عهده شرکت | H14: خرابی کلید فشاری | I14: 1405/06/12 | J14: 1404/10/02 | L14: =IF(OR(TRIM(I14)="",TRIM(K14)=""),"",IFERROR((VALUE(LEFT(TRIM(I14),4))-VALUE(LEFT(TRIM(K14),4)))*12+VALUE(MID(TRIM(I14),6,2))-VALUE(MID(TRIM(K14),6,2)),"")) | M14: =IF(TRIM(H14)="","",IFERROR(LOOKUP(2,1/(ISNUMBER(SEARCH('منطق دسته‌بندی'!$A$2:$A$187,H14))),'منطق دسته‌بندی'!$B$2:$B$187),"سایر (نیازمند بررسی دستی)")) -> کلید فشاری (تعویض/بازبینی) | N14: MINI کليد فشاري يخچال | O14: {=IF(A14="","",IF(SUMPRODUCT(($B$2:$B$965=B14)*($C$2:$C$965=C14)*($D$2:$D$965=D14)*($E$2:$E$965=E14)*($F$2:$F$965=F14)*($G$2:$G$965=G14)*($H$2:$H$965=H14)*($I$2:$I$965=I14)*($J$2:$J$965=J14)*($K$2:$K$965=K14)*($N$2:$N$965=N14))=1,"خیر",IF(SUMPRODUCT(($B$2:B14=B14)*($C$2:C14=C14)*($D$2:D14=D14)*($E$2:E14=E14)*($F$2:F14=F14)*($G$2:G14=G14)*($H$2:H14=H14)*($I$2:I14=I14)*($J$2:J14=J14)*($K$2:K14=K14)*($N$2:N14=N14))=1,"بله-1","بله")))} -> خیر | P14: {=IF(A14="","",IF(SUMPRODUCT(($F$2:$F$969=F14)*($I$2:$I$969=I14))=1,"خیر",IF(SUMPRODUCT(($F$2:F14=F14)*($I$2:I14=I14))=1,"بله-1","بله")))} -> خیر
A15: 310008317 | B15: مرداد | C15: 1405-05 | D15: یخچال مینی | E15: CM-RS5BK2 | F15: 52240004N00311 | G15: خاموش و روشن شدن LED کاور / سقفي**اياب و ذهاب به عهده شرکت | H15: خرابی کلید فشاری | I15: 1405/05/24 | J15: 1403/11/25 | K15: 1405/04/16 | L15: =IF(OR(TRIM(I15)="",TRIM(K15)=""),"",IFERROR((VALUE(LEFT(TRIM(I15),4))-VALUE(LEFT(TRIM(K15),4)))*12+VALUE(MID(TRIM(I15),6,2))-VALUE(MID(TRIM(K15),6,2)),"")) -> 1 | M15: =IF(TRIM(H15)="","",IFERROR(LOOKUP(2,1/(ISNUMBER(SEARCH('منطق دسته‌بندی'!$A$2:$A$187,H15))),'منطق دسته‌بندی'!$B$2:$B$187),"سایر (نیازمند بررسی دستی)")) -> کلید فشاری (تعویض/بازبینی) | N15: MINI کليد فشاري يخچال | O15: {=IF(A15="","",IF(SUMPRODUCT(($B$2:$B$965=B15)*($C$2:$C$965=C15)*($D$2:$D$965=D15)*($E$2:$E$965=E15)*($F$2:$F$965=F15)*($G$2:$G$965=G15)*($H$2:$H$965=H15)*($I$2:$I$965=I15)*($J$2:$J$965=J15)*($K$2:$K$965=K15)*($N$2:$N$965=N15))=1,"خیر",IF(SUMPRODUCT(($B$2:B15=B15)*($C$2:C15=C15)*($D$2:D15=D15)*($E$2:E15=E15)*($F$2:F15=F15)*($G$2:G15=G15)*($H$2:H15=H15)*($I$2:I15=I15)*($J$2:J15=J15)*($K$2:K15=K15)*($N$2:N15=N15))=1,"بله-1","بله")))} -> خیر | P15: {=IF(A15="","",IF(SUMPRODUCT(($F$2:$F$969=F15)*($I$2:$I$969=I15))=1,"خیر",IF(SUMPRODUCT(($F$2:F15=F15)*($I$2:I15=I15))=1,"بله-1","بله")))} -> خیر
A16: 210006788 | B16: اردیبهشت | C16: 1405-02 | D16: یخچال مینی | E16: CM-RS5BK2 | F16: 52240004N00285 | G16: گرم شدن محصول — ایاب و ذهاب به عهده شرکت | H16: سوختن کمپرسور - یخچال مینی | I16: 1405/02/29 | J16: 1403/11/24 | K16: 1404/02/30 | L16: =IF(OR(TRIM(I16)="",TRIM(K16)=""),"",IFERROR((VALUE(LEFT(TRIM(I16),4))-VALUE(LEFT(TRIM(K16),4)))*12+VALUE(MID(TRIM(I16),6,2))-VALUE(MID(TRIM(K16),6,2)),"")) -> 12 | M16: =IF(TRIM(H16)="","",IFERROR(LOOKUP(2,1/(ISNUMBER(SEARCH('منطق دسته‌بندی'!$A$2:$A$187,H16))),'منطق دسته‌بندی'!$B$2:$B$187),"سایر (نیازمند بررسی دستی)")) -> خرابی - کمپرسور (تعویض) | N16: کمپرسور مینی | O16: {=IF(A16="","",IF(SUMPRODUCT(($B$2:$B$965=B16)*($C$2:$C$965=C16)*($D$2:$D$965=D16)*($E$2:$E$965=E16)*($F$2:$F$965=F16)*($G$2:$G$965=G16)*($H$2:$H$965=H16)*($I$2:$I$965=I16)*($J$2:$J$965=J16)*($K$2:$K$965=K16)*($N$2:$N$965=N16))=1,"خیر",IF(SUMPRODUCT(($B$2:B16=B16)*($C$2:C16=C16)*($D$2:D16=D16)*($E$2:E16=E16)*($F$2:F16=F16)*($G$2:G16=G16)*($H$2:H16=H16)*($I$2:I16=I16)*($J$2:J16=J16)*($K$2:K16=K16)*($N$2:N16=N16))=1,"بله-1","بله")))} -> خیر | P16: {=IF(A16="","",IF(SUMPRODUCT(($F$2:$F$969=F16)*($I$2:$I$969=I16))=1,"خیر",IF(SUMPRODUCT(($F$2:F16=F16)*($I$2:I16=I16))=1,"بله-1","بله")))} -> خیر
A17: 210005280 | B17: فروردین | C17: 1405-01 | D17: یخچال مینی | E17: MINI-R (BLACK) | F17: 52240004N00055 | G17: افتادگی درب/ تنظیم درب — ایاب و ذهاب به عهده شرکت | H17: تعویض لولا | I17: 1405/01/16 | J17: 1403/08/13 | K17: 1403/12/25 | L17: =IF(OR(TRIM(I17)="",TRIM(K17)=""),"",IFERROR((VALUE(LEFT(TRIM(I17),4))-VALUE(LEFT(TRIM(K17),4)))*12+VALUE(MID(TRIM(I17),6,2))-VALUE(MID(TRIM(K17),6,2)),"")) -> 13 | M17: =IF(TRIM(H17)="","",IFERROR(LOOKUP(2,1/(ISNUMBER(SEARCH('منطق دسته‌بندی'!$A$2:$A$187,H17))),'منطق دسته‌بندی'!$B$2:$B$187),"سایر (نیازمند بررسی دستی)")) -> مکانیزم درب - لولا (تعویض/تنظیم) | N17: لولا درب | O17: {=IF(A17="","",IF(SUMPRODUCT(($B$2:$B$965=B17)*($C$2:$C$965=C17)*($D$2:$D$965=D17)*($E$2:$E$965=E17)*($F$2:$F$965=F17)*($G$2:$G$965=G17)*($H$2:$H$965=H17)*($I$2:$I$965=I17)*($J$2:$J$965=J17)*($K$2:$K$965=K17)*($N$2:$N$965=N17))=1,"خیر",IF(SUMPRODUCT(($B$2:B17=B17)*($C$2:C17=C17)*($D$2:D17=D17)*($E$2:E17=E17)*($F$2:F17=F17)*($G$2:G17=G17)*($H$2:H17=H17)*($I$2:I17=I17)*($J$2:J17=J17)*($K$2:K17=K17)*($N$2:N17=N17))=1,"بله-1","بله")))} -> خیر | P17: {=IF(A17="","",IF(SUMPRODUCT(($F$2:$F$969=F17)*($I$2:$I$969=I17))=1,"خیر",IF(SUMPRODUCT(($F$2:F17=F17)*($I$2:I17=I17))=1,"بله-1","بله")))} -> خیر
A18: 210022043 | B18: مرداد | C18: 1405-05 | D18: یخچال مینی | E18: CM-RS5RE1 | F18: 52240003N02110 | G18: خاموش بودن LED کاور / سقفي**اياب و ذهاب به عهده شرکت | H18: خرابی کلید فشاری | I18: 1405/05/26 | J18: 1405/03/13 | K18: 1405/05/21 | L18: =IF(OR(TRIM(I18)="",TRIM(K18)=""),"",IFERROR((VALUE(LEFT(TRIM(I18),4))-VALUE(LEFT(TRIM(K18),4)))*12+VALUE(MID(TRIM(I18),6,2))-VALUE(MID(TRIM(K18),6,2)),"")) -> 0 | M18: =IF(TRIM(H18)="","",IFERROR(LOOKUP(2,1/(ISNUMBER(SEARCH('منطق دسته‌بندی'!$A$2:$A$187,H18))),'منطق دسته‌بندی'!$B$2:$B$187),"سایر (نیازمند بررسی دستی)")) -> کلید فشاری (تعویض/بازبینی) | N18: MINI کليد فشاري يخچال | O18: {=IF(A18="","",IF(SUMPRODUCT(($B$2:$B$965=B18)*($C$2:$C$965=C18)*($D$2:$D$965=D18)*($E$2:$E$965=E18)*($F$2:$F$965=F18)*($G$2:$G$965=G18)*($H$2:$H$965=H18)*($I$2:$I$965=I18)*($J$2:$J$965=J18)*($K$2:$K$965=K18)*($N$2:$N$965=N18))=1,"خیر",IF(SUMPRODUCT(($B$2:B18=B18)*($C$2:C18=C18)*($D$2:D18=D18)*($E$2:E18=E18)*($F$2:F18=F18)*($G$2:G18=G18)*($H$2:H18=H18)*($I$2:I18=I18)*($J$2:J18=J18)*($K$2:K18=K18)*($N$2:N18=N18))=1,"بله-1","بله")))} -> خیر | P18: {=IF(A18="","",IF(SUMPRODUCT(($F$2:$F$969=F18)*($I$2:$I$969=I18))=1,"خیر",IF(SUMPRODUCT(($F$2:F18=F18)*($I$2:I18=I18))=1,"بله-1","بله")))} -> خیر
A19: 210013253 | B19: خرداد | C19: 1405-03 | D19: یخچال مینی | E19: CM-RS5RE1 | F19: 52240003N01957 | G19: خاموش بودن LED کاور / سقفی — ایاب و ذهاب به عهده شرکت | H19: خرابی ال ای دی داخل کابین - یخچال مینی | I19: 1405/03/09 | J19: 1405/03/04 | K19: 1405/03/04 | L19: =IF(OR(TRIM(I19)="",TRIM(K19)=""),"",IFERROR((VALUE(LEFT(TRIM(I19),4))-VALUE(LEFT(TRIM(K19),4)))*12+VALUE(MID(TRIM(I19),6,2))-VALUE(MID(TRIM(K19),6,2)),"")) -> 0 | M19: =IF(TRIM(H19)="","",IFERROR(LOOKUP(2,1/(ISNUMBER(SEARCH('منطق دسته‌بندی'!$A$2:$A$187,H19))),'منطق دسته‌بندی'!$B$2:$B$187),"سایر (نیازمند بررسی دستی)")) -> خرابی - لامپ/LED داخلی (تعویض) | N19: لامپ مینی | O19: {=IF(A19="","",IF(SUMPRODUCT(($B$2:$B$965=B19)*($C$2:$C$965=C19)*($D$2:$D$965=D19)*($E$2:$E$965=E19)*($F$2:$F$965=F19)*($G$2:$G$965=G19)*($H$2:$H$965=H19)*($I$2:$I$965=I19)*($J$2:$J$965=J19)*($K$2:$K$965=K19)*($N$2:$N$965=N19))=1,"خیر",IF(SUMPRODUCT(($B$2:B19=B19)*($C$2:C19=C19)*($D$2:D19=D19)*($E$2:E19=E19)*($F$2:F19=F19)*($G$2:G19=G19)*($H$2:H19=H19)*($I$2:I19=I19)*($J$2:J19=J19)*($K$2:K19=K19)*($N$2:N19=N19))=1,"بله-1","بله")))} -> خیر | P19: {=IF(A19="","",IF(SUMPRODUCT(($F$2:$F$969=F19)*($I$2:$I$969=I19))=1,"خیر",IF(SUMPRODUCT(($F$2:F19=F19)*($I$2:I19=I19))=1,"بله-1","بله")))} -> خیر
A20: 210023074 | B20: شهریور | C20: 1405-06 | D20: یخچال مینی | E20: CM-RS5RE1 | F20: 52240003N01352 | G20: خاموش بودن LED کاور / سقفي ** اياب و ذهاب به عهده شرکت | H20: خرابی LED | I20: 1405/06/11 | J20: 1404/09/11 | K20: 1405/06/10 | L20: =IF(OR(TRIM(I20)="",TRIM(K20)=""),"",IFERROR((VALUE(LEFT(TRIM(I20),4))-VALUE(LEFT(TRIM(K20),4)))*12+VALUE(MID(TRIM(I20),6,2))-VALUE(MID(TRIM(K20),6,2)),"")) -> 0 | M20: =IF(TRIM(H20)="","",IFERROR(LOOKUP(2,1/(ISNUMBER(SEARCH('منطق دسته‌بندی'!$A$2:$A$187,H20))),'منطق دسته‌بندی'!$B$2:$B$187),"سایر (نیازمند بررسی دستی)")) -> خرابی - لامپ/LED داخلی (تعویض) | N20: MINI LED یخچال | O20: {=IF(A20="","",IF(SUMPRODUCT(($B$2:$B$965=B20)*($C$2:$C$965=C20)*($D$2:$D$965=D20)*($E$2:$E$965=E20)*($F$2:$F$965=F20)*($G$2:$G$965=G20)*($H$2:$H$965=H20)*($I$2:$I$965=I20)*($J$2:$J$965=J20)*($K$2:$K$965=K20)*($N$2:$N$965=N20))=1,"خیر",IF(SUMPRODUCT(($B$2:B20=B20)*($C$2:C20=C20)*($D$2:D20=D20)*($E$2:E20=E20)*($F$2:F20=F20)*($G$2:G20=G20)*($H$2:H20=H20)*($I$2:I20=I20)*($J$2:J20=J20)*($K$2:K20=K20)*($N$2:N20=N20))=1,"بله-1","بله")))} -> خیر | P20: {=IF(A20="","",IF(SUMPRODUCT(($F$2:$F$969=F20)*($I$2:$I$969=I20))=1,"خیر",IF(SUMPRODUCT(($F$2:F20=F20)*($I$2:I20=I20))=1,"بله-1","بله")))} -> خیر
A21: 210023894 | B21: شهریور | C21: 1405-06 | D21: یخچال مینی | E21: CM-RS5RE1 | F21: 52240003N01318 | G21: خاموش و روشن شدن LED کاور / سقفي**اياب و ذهاب به عهده شرکت | H21: خرابی LED | I21: 1405/06/16 | J21: 1404/09/09 | K21: 1405/01/19 | L21: =IF(OR(TRIM(I21)="",TRIM(K21)=""),"",IFERROR((VALUE(LEFT(TRIM(I21),4))-VALUE(LEFT(TRIM(K21),4)))*12+VALUE(MID(TRIM(I21),6,2))-VALUE(MID(TRIM(K21),6,2)),"")) -> 5 | M21: =IF(TRIM(H21)="","",IFERROR(LOOKUP(2,1/(ISNUMBER(SEARCH('منطق دسته‌بندی'!$A$2:$A$187,H21))),'منطق دسته‌بندی'!$B$2:$B$187),"سایر (نیازمند بررسی دستی)")) -> خرابی - لامپ/LED داخلی (تعویض) | N21: MINI LED یخچال | O21: {=IF(A21="","",IF(SUMPRODUCT(($B$2:$B$965=B21)*($C$2:$C$965=C21)*($D$2:$D$965=D21)*($E$2:$E$965=E21)*($F$2:$F$965=F21)*($G$2:$G$965=G21)*($H$2:$H$965=H21)*($I$2:$I$965=I21)*($J$2:$J$965=J21)*($K$2:$K$965=K21)*($N$2:$N$965=N21))=1,"خیر",IF(SUMPRODUCT(($B$2:B21=B21)*($C$2:C21=C21)*($D$2:D21=D21)*($E$2:E21=E21)*($F$2:F21=F21)*($G$2:G21=G21)*($H$2:H21=H21)*($I$2:I21=I21)*($J$2:J21=J21)*($K$2:K21=K21)*($N$2:N21=N21))=1,"بله-1","بله")))} -> خیر | P21: {=IF(A21="","",IF(SUMPRODUCT(($F$2:$F$969=F21)*($I$2:$I$969=I21))=1,"خیر",IF(SUMPRODUCT(($F$2:F21=F21)*($I$2:I21=I21))=1,"بله-1","بله")))} -> خیر
A22: 210009809 | B22: اردیبهشت | C22: 1405-02 | D22: یخچال مینی | E22: CM-RS5RE1 | F22: 52240003N01096 | G22: خاموش بودن LED کاور / سقفی — ایاب و ذهاب به عهده شرکت | H22: خرابی ال ای دی داخل کابین - یخچال مینی | I22: 1405/02/28 | J22: 1403/12/16 | K22: 1404/06/29 | L22: =IF(OR(TRIM(I22)="",TRIM(K22)=""),"",IFERROR((VALUE(LEFT(TRIM(I22),4))-VALUE(LEFT(TRIM(K22),4)))*12+VALUE(MID(TRIM(I22),6,2))-VALUE(MID(TRIM(K22),6,2)),"")) -> 8 | M22: =IF(TRIM(H22)="","",IFERROR(LOOKUP(2,1/(ISNUMBER(SEARCH('منطق دسته‌بندی'!$A$2:$A$187,H22))),'منطق دسته‌بندی'!$B$2:$B$187),"سایر (نیازمند بررسی دستی)")) -> خرابی - لامپ/LED داخلی (تعویض) | N22: لامپ مینی | O22: {=IF(A22="","",IF(SUMPRODUCT(($B$2:$B$965=B22)*($C$2:$C$965=C22)*($D$2:$D$965=D22)*($E$2:$E$965=E22)*($F$2:$F$965=F22)*($G$2:$G$965=G22)*($H$2:$H$965=H22)*($I$2:$I$965=I22)*($J$2:$J$965=J22)*($K$2:$K$965=K22)*($N$2:$N$965=N22))=1,"خیر",IF(SUMPRODUCT(($B$2:B22=B22)*($C$2:C22=C22)*($D$2:D22=D22)*($E$2:E22=E22)*($F$2:F22=F22)*($G$2:G22=G22)*($H$2:H22=H22)*($I$2:I22=I22)*($J$2:J22=J22)*($K$2:K22=K22)*($N$2:N22=N22))=1,"بله-1","بله")))} -> خیر | P22: {=IF(A22="","",IF(SUMPRODUCT(($F$2:$F$969=F22)*($I$2:$I$969=I22))=1,"خیر",IF(SUMPRODUCT(($F$2:F22=F22)*($I$2:I22=I22))=1,"بله-1","بله")))} -> خیر
A23: 510022914 | B23: مرداد | C23: 1405-05 | D23: یخچال مینی | E23: CM-RS5RE1 | F23: 52240003N01043 | G23: کسری قطعات پک بسته بندی - کد قطعه در لیست اقدامات درج می گردد. — ایاب و ذهاب به عهده شرکت | H23: کسری قطعات تزئینی پک قطعات داخلی | I23: 1405/05/05 | J23: 1403/12/26 | K23: 1405/05/03 | L23: =IF(OR(TRIM(I23)="",TRIM(K23)=""),"",IFERROR((VALUE(LEFT(TRIM(I23),4))-VALUE(LEFT(TRIM(K23),4)))*12+VALUE(MID(TRIM(I23),6,2))-VALUE(MID(TRIM(K23),6,2)),"")) -> 0 | M23: =IF(TRIM(H23)="","",IFERROR(LOOKUP(2,1/(ISNUMBER(SEARCH('منطق دسته‌بندی'!$A$2:$A$187,H23))),'منطق دسته‌بندی'!$B$2:$B$187),"سایر (نیازمند بررسی دستی)")) -> قطعات تزئینی - شکستگی/کسری (تعویض) | N23: MINI شلف بزرگ یخچال | O23: {=IF(A23="","",IF(SUMPRODUCT(($B$2:$B$965=B23)*($C$2:$C$965=C23)*($D$2:$D$965=D23)*($E$2:$E$965=E23)*($F$2:$F$965=F23)*($G$2:$G$965=G23)*($H$2:$H$965=H23)*($I$2:$I$965=I23)*($J$2:$J$965=J23)*($K$2:$K$965=K23)*($N$2:$N$965=N23))=1,"خیر",IF(SUMPRODUCT(($B$2:B23=B23)*($C$2:C23=C23)*($D$2:D23=D23)*($E$2:E23=E23)*($F$2:F23=F23)*($G$2:G23=G23)*($H$2:H23=H23)*($I$2:I23=I23)*($J$2:J23=J23)*($K$2:K23=K23)*($N$2:N23=N23))=1,"بله-1","بله")))} -> خیر | P23: {=IF(A23="","",IF(SUMPRODUCT(($F$2:$F$969=F23)*($I$2:$I$969=I23))=1,"خیر",IF(SUMPRODUCT(($F$2:F23=F23)*($I$2:I23=I23))=1,"بله-1","بله")))} -> خیر
A24: 130011786 | B24: شهریور | C24: 1405-06 | D24: يخچال ميني | E24: MINI-R | F24: 52240003N01015 | G24: خاموش و روشن شدن LED کاور / سقفي ** اياب و ذهاب به عهده مشتري | H24: خرابی LED | I24: 1405/06/21 | J24: 1403/12/19 | K24: 1404/06/03 | L24: =IF(OR(TRIM(I24)="",TRIM(K24)=""),"",IFERROR((VALUE(LEFT(TRIM(I24),4))-VALUE(LEFT(TRIM(K24),4)))*12+VALUE(MID(TRIM(I24),6,2))-VALUE(MID(TRIM(K24),6,2)),"")) -> 12 | M24: =IF(OR(ISNUMBER(SEARCH("بدون مورد",H24)),ISNUMBER(SEARCH("غير گارانتي",H24)),ISNUMBER(SEARCH("غیر گارانتی",H24)),ISNUMBER(SEARCH("بدون اجرت",H24)),ISNUMBER(SEARCH("فيلتر",H24)),ISNUMBER(SEARCH("فیلتر",H24))),"غیرگارانتی/بدون قطعه",IF(OR(ISNUMBER(SEARCH("ريست",H24)),ISNUMBER(SEARCH("ریست",H24))),"ریست نرم‌افزاری (بدون قطعه)",IF(OR(ISNUMBER(SEARCH("تعویض محصول",H24)),ISNUMBER(SEARCH("تعویض دستگاه",H24))),"تعویض کامل دستگاه (Replacement)",IF(ISNUMBER(SEARCH("پمپ",H24)),IF(ISNUMBER(SEARCH("نشت",H24)),"نشتی - پمپ تخلیه (تعمیر/آب‌بندی)","خرابی - پمپ تخلیه (تعویض)"),IF(ISNUMBER(SEARCH("کمپرسور",H24)),"خرابی - کمپرسور (تعویض)",IF(ISNUMBER(SEARCH("کمک فنر",H24)),"خرابی - کمک فنر (تعویض)",IF(ISNUMBER(SEARCH("لولا",H24)),"مکانیزم درب - لولا (تعویض)",IF(OR(ISNUMBER(SEARCH("قلاب",H24)),ISNUMBER(SEARCH("ميکروسوئيچ",H24)),ISNUMBER(SEARCH("میکروسوئیچ",H24))),"مکانیزم درب - میکروسوئیچ/قلاب (تعویض/تنظیم)",IF(ISNUMBER(SEARCH("زبانه",H24)),"مکانیزم درب - زبانه (تعویض)",IF(OR(ISNUMBER(SEARCH("شيلنگ",H24)),ISNUMBER(SEARCH("شیلنگ",H24))),IF(OR(ISNUMBER(SEARCH("نشتی",H24)),ISNUMBER(SEARCH("نشتي",H24))),"نشتی - شیلنگ (تعمیر/آب‌بندی)",IF(OR(ISNUMBER(SEARCH("يخ",H24)),ISNUMBER(SEARCH("یخ",H24))),"شیلنگ یخساز - یخ‌زدگی (بازبینی)","شیلنگ - برخورد/لهیدگی (بازبینی)")),IF(OR(ISNUMBER(SEARCH("تنظيم ديسپل",H24)),ISNUMBER(SEARCH("تنظیم دیسپل",H24)),ISNUMBER(SEARCH("تنظيم صفحه نمايش",H24)),ISNUMBER(SEARCH("تنظیم صفحه نمایش",H24))),"تنظیم - تنظیمات دستگاه/دیسپلی (تعمیر)",IF(OR(ISNUMBER(SEARCH("برد",H24)),ISNUMBER(SEARCH("سوکت",H24)),ISNUMBER(SEARCH("ديسپل",H24)),ISNUMBER(SEARCH("دیسپل",H24))),"خرابی - برد الکترونیک (تعویض)",IF(OR(ISNUMBER(SEARCH("يخساز",H24)),ISNUMBER(SEARCH("یخساز",H24)),ISNUMBER(SEARCH("دمپر",H24))),IF(OR(ISNUMBER(SEARCH("خرابی",H24)),ISNUMBER(SEARCH("خراب",H24)),ISNUMBER(SEARCH("عدم کارکرد",H24)),ISNUMBER(SEARCH("عدم عملکرد",H24))),"یخساز - خرابی موتور/سنسور/برد (تعویض)","یخساز - تنظیم/عایق (تعمیر)"),IF(OR(ISNUMBER(SEARCH("لاستيک",H24)),ISNUMBER(SEARCH("لاستیک",H24))),"لاستیک درزگیر - دفرمگی/پارگی (تعویض)",IF(OR(ISNUMBER(SEARCH("گسکت",H24)),ISNUMBER(SEARCH("گسگت",H24))),"لاستیک درزگیر - دفرمگی/پارگی (تعویض)",IF(ISNUMBER(SEARCH("مخزن نمک",H24)),"نشتی - درب مخزن نمک (تعمیر/آب‌بندی)",IF(ISNUMBER(SEARCH("براکت",H24)),"نشتی - براکت ریل (تعمیر/آب‌بندی)",IF(ISNUMBER(SEARCH("جاپودر",H24)),"نشتی - جاپودری (تعمیر/آب‌بندی)",IF(ISNUMBER(SEARCH("مقسم",H24)),"نشتی - مقسم آب (تعمیر/آب‌بندی)",IF(OR(ISNUMBER(SEARCH("سنسور دما",H24)),ISNUMBER(SEARCH("ترموستات",H24))),"خرابی - ترموستات (تعویض)",IF(OR(ISNUMBER(SEARCH("هيدروستات",H24)),ISNUMBER(SEARCH("هیدروستات",H24))),"خرابی - هیدروستات (تعویض)",IF(OR(ISNUMBER(SEARCH("بلبرينگ",H24)),ISNUMBER(SEARCH("بلبرینگ",H24))),"خرابی - بلبرینگ (تعویض)",IF(OR(ISNUMBER(SEARCH("شيربرق",H24)),ISNUMBER(SEARCH("شیربرق",H24))),"خرابی - شیربرقی (تعویض)",IF(OR(ISNUMBER(SEARCH("واتر جت",H24)),ISNUMBER(SEARCH("واترجت",H24))),"خرابی - واترجت (تعویض)",IF(OR(ISNUMBER(SEARCH("سيم",H24)),ISNUMBER(SEARCH("سیم",H24)),ISNUMBER(SEARCH("اتصال",H24))),"سیم‌کشی/اتصالات (تعویض/بازبینی)",IF(OR(ISNUMBER(SEARCH("تصوير",H24)),ISNUMBER(SEARCH("تصویر",H24))),"برد نمایش تلویزیون (تعویض)",IF(OR(ISNUMBER(SEARCH("ريموت",H24)),ISNUMBER(SEARCH("ریموت",H24))),"ریموت کنترل (تعویض/تعمیر)",IF(OR(ISNUMBER(SEARCH("ال اي دي",H24)),ISNUMBER(SEARCH("ال ای دی",H24)),ISNUMBER(SEARCH("LED",H24))),"خرابی - لامپ/LED داخلی (تعویض)",IF(ISNUMBER(SEARCH("زنگ زدگ",H24)),"زنگ‌زدگی بدنه/قطعه (تعویض)",IF(OR(ISNUMBER(SEARCH("قطعات تزئين",H24)),ISNUMBER(SEARCH("قطعات تزئین",H24))),"قطعات تزئینی - شکستگی/کسری (تعویض)",IF(ISNUMBER(SEARCH("سبد",H24)),"سبد ظرفشویی - شکستگی (تعویض)",IF(ISNUMBER(SEARCH("تاب درام",H24)),"خرابی - تاب برداشتن درام (تعویض)",IF(ISNUMBER(SEARCH("درام",H24)),"خرابی - سایر ایراد درام (تعویض)",IF(ISNUMBER(SEARCH("موتور",H24)),"خرابی - موتور (تعویض)",IF(ISNUMBER(SEARCH("تسمه",H24)),"خرابی - تسمه (تعویض)",IF(OR(ISNUMBER(SEARCH("پيچ ولوم",H24)),ISNUMBER(SEARCH("پیچ ولوم",H24))),"تنظیم - پیچ ولوم/دکمه (تعمیر)",IF(OR(ISNUMBER(SEARCH("کسري قطعات",H24)),ISNUMBER(SEARCH("کسری قطعات",H24))),"کسری قطعات تزئینی (تعویض)",IF(ISNUMBER(SEARCH("پرچ",H24)),"پرچ/بدنه کابین(تعمیر)",IF(OR(ISNUMBER(SEARCH("نشت",H24)),ISNUMBER(SEARCH("آبريزش",H24)),ISNUMBER(SEARCH("آبریزش",H24))),"نشتی آب - محل نامشخص (نیازمند بازدید)",IF(ISNUMBER(SEARCH("درب",H24)),"سایر اجزای درب (بازبینی)",IF(ISNUMBER(SEARCH("ضربه",H24)),"بدنه/کابین - ضربه (بازبینی/تعویض پنل)",IF(ISNUMBER(SEARCH("تراز",H24)),"تراز/لرزش - نصب (رگلاژ پایه)",IF(OR(ISNUMBER(SEARCH("تعویض",H24)),ISNUMBER(SEARCH("تعويض",H24))),"تعویض کامل دستگاه (Replacement)","سایر (نیازمند بررسی دستی)"))))))))))))))))))))))))))))))))))))))))))) -> خرابی - لامپ/LED داخلی (تعویض) | N24: MINI LED یخچال | O24: {=IF(A24="","",IF(SUMPRODUCT(($B$2:$B$965=B24)*($C$2:$C$965=C24)*($D$2:$D$965=D24)*($E$2:$E$965=E24)*($F$2:$F$965=F24)*($G$2:$G$965=G24)*($H$2:$H$965=H24)*($I$2:$I$965=I24)*($J$2:$J$965=J24)*($K$2:$K$965=K24)*($N$2:$N$965=N24))=1,"خیر",IF(SUMPRODUCT(($B$2:B24=B24)*($C$2:C24=C24)*($D$2:D24=D24)*($E$2:E24=E24)*($F$2:F24=F24)*($G$2:G24=G24)*($H$2:H24=H24)*($I$2:I24=I24)*($J$2:J24=J24)*($K$2:K24=K24)*($N$2:N24=N24))=1,"بله-1","بله")))} -> خیر | P24: {=IF(A24="","",IF(SUMPRODUCT(($F$2:$F$969=F24)*($I$2:$I$969=I24))=1,"خیر",IF(SUMPRODUCT(($F$2:F24=F24)*($I$2:I24=I24))=1,"بله-1","بله")))} -> خیر
A25: 210016840 | B25: مرداد | C25: 1405-05 | D25: یخچال مینی | E25: CM-RS5RE1 | F25: 52240003N01005 | G25: شکستگی دستگیره — ایاب و ذهاب به عهده شرکت | H25: شکستگی دستگیره | I25: 1405/05/02 | J25: 1404/01/14 | L25: =IF(OR(TRIM(I25)="",TRIM(K25)=""),"",IFERROR((VALUE(LEFT(TRIM(I25),4))-VALUE(LEFT(TRIM(K25),4)))*12+VALUE(MID(TRIM(I25),6,2))-VALUE(MID(TRIM(K25),6,2)),"")) | M25: =IF(TRIM(H25)="","",IFERROR(LOOKUP(2,1/(ISNUMBER(SEARCH('منطق دسته‌بندی'!$A$2:$A$187,H25))),'منطق دسته‌بندی'!$B$2:$B$187),"سایر (نیازمند بررسی دستی)")) -> مکانیزم درب - دستگیره (تعویض) | N25: MINI دستگیره درب یخچال | O25: {=IF(A25="","",IF(SUMPRODUCT(($B$2:$B$965=B25)*($C$2:$C$965=C25)*($D$2:$D$965=D25)*($E$2:$E$965=E25)*($F$2:$F$965=F25)*($G$2:$G$965=G25)*($H$2:$H$965=H25)*($I$2:$I$965=I25)*($J$2:$J$965=J25)*($K$2:$K$965=K25)*($N$2:$N$965=N25))=1,"خیر",IF(SUMPRODUCT(($B$2:B25=B25)*($C$2:C25=C25)*($D$2:D25=D25)*($E$2:E25=E25)*($F$2:F25=F25)*($G$2:G25=G25)*($H$2:H25=H25)*($I$2:I25=I25)*($J$2:J25=J25)*($K$2:K25=K25)*($N$2:N25=N25))=1,"بله-1","بله")))} -> خیر | P25: {=IF(A25="","",IF(SUMPRODUCT(($F$2:$F$969=F25)*($I$2:$I$969=I25))=1,"خیر",IF(SUMPRODUCT(($F$2:F25=F25)*($I$2:I25=I25))=1,"بله-1","بله")))} -> خیر
A26: 810004918 | B26: مرداد | C26: 1405-05 | D26: یخچال مینی | E26: CM-RS5RE1 | F26: 52240003N00980 | G26: خاموش بودن LED کاور / سقفی — ایاب و ذهاب به عهده شرکت | H26: MINI کلید فشاری یخچال | I26: 1405/05/04 | J26: 1403/12/27 | K26: 1405/04/30 | L26: =IF(OR(TRIM(I26)="",TRIM(K26)=""),"",IFERROR((VALUE(LEFT(TRIM(I26),4))-VALUE(LEFT(TRIM(K26),4)))*12+VALUE(MID(TRIM(I26),6,2))-VALUE(MID(TRIM(K26),6,2)),"")) -> 1 | M26: =IF(TRIM(H26)="","",IFERROR(LOOKUP(2,1/(ISNUMBER(SEARCH('منطق دسته‌بندی'!$A$2:$A$187,H26))),'منطق دسته‌بندی'!$B$2:$B$187),"سایر (نیازمند بررسی دستی)")) -> کلید فشاری (تعویض/بازبینی) | N26: MINI کلید فشاری یخچال | O26: {=IF(A26="","",IF(SUMPRODUCT(($B$2:$B$965=B26)*($C$2:$C$965=C26)*($D$2:$D$965=D26)*($E$2:$E$965=E26)*($F$2:$F$965=F26)*($G$2:$G$965=G26)*($H$2:$H$965=H26)*($I$2:$I$965=I26)*($J$2:$J$965=J26)*($K$2:$K$965=K26)*($N$2:$N$965=N26))=1,"خیر",IF(SUMPRODUCT(($B$2:B26=B26)*($C$2:C26=C26)*($D$2:D26=D26)*($E$2:E26=E26)*($F$2:F26=F26)*($G$2:G26=G26)*($H$2:H26=H26)*($I$2:I26=I26)*($J$2:J26=J26)*($K$2:K26=K26)*($N$2:N26=N26))=1,"بله-1","بله")))} -> خیر | P26: {=IF(A26="","",IF(SUMPRODUCT(($F$2:$F$969=F26)*($I$2:$I$969=I26))=1,"خیر",IF(SUMPRODUCT(($F$2:F26=F26)*($I$2:I26=I26))=1,"بله-1","بله")))} -> خیر
A27: 130009846 | B27: مرداد | C27: 1405-05 | D27: یخچال مینی | E27: CM-RS5RE1 | F27: 52240003N00957 | G27: خاموش بودن LED کاور / سقفی — ایاب و ذهاب به عهده شرکت | H27: خرابی LED | I27: 1405/05/19 | J27: 1403/12/10 | K27: 1404/07/03 | L27: =IF(OR(TRIM(I27)="",TRIM(K27)=""),"",IFERROR((VALUE(LEFT(TRIM(I27),4))-VALUE(LEFT(TRIM(K27),4)))*12+VALUE(MID(TRIM(I27),6,2))-VALUE(MID(TRIM(K27),6,2)),"")) -> 10 | M27: =IF(TRIM(H27)="","",IFERROR(LOOKUP(2,1/(ISNUMBER(SEARCH('منطق دسته‌بندی'!$A$2:$A$187,H27))),'منطق دسته‌بندی'!$B$2:$B$187),"سایر (نیازمند بررسی دستی)")) -> خرابی - لامپ/LED داخلی (تعویض) | N27: MINI LED یخچال | O27: {=IF(A27="","",IF(SUMPRODUCT(($B$2:$B$965=B27)*($C$2:$C$965=C27)*($D$2:$D$965=D27)*($E$2:$E$965=E27)*($F$2:$F$965=F27)*($G$2:$G$965=G27)*($H$2:$H$965=H27)*($I$2:$I$965=I27)*($J$2:$J$965=J27)*($K$2:$K$965=K27)*($N$2:$N$965=N27))=1,"خیر",IF(SUMPRODUCT(($B$2:B27=B27)*($C$2:C27=C27)*($D$2:D27=D27)*($E$2:E27=E27)*($F$2:F27=F27)*($G$2:G27=G27)*($H$2:H27=H27)*($I$2:I27=I27)*($J$2:J27=J27)*($K$2:K27=K27)*($N$2:N27=N27))=1,"بله-1","بله")))} -> خیر | P27: {=IF(A27="","",IF(SUMPRODUCT(($F$2:$F$969=F27)*($I$2:$I$969=I27))=1,"خیر",IF(SUMPRODUCT(($F$2:F27=F27)*($I$2:I27=I27))=1,"بله-1","بله")))} -> خیر
A28: 130011682 | B28: شهریور | C28: 1405-06 | D28: یخچال مینی | E28: CM-RS5RE1 | F28: 52240003N00836 | G28: خاموش بودن LED کاور / سقفي ** اياب و ذهاب به عهده شرکت | H28: خرابی LED | I28: 1405/06/18 | J28: 1403/12/03 | K28: 1405/02/21 | L28: =IF(OR(TRIM(I28)="",TRIM(K28)=""),"",IFERROR((VALUE(LEFT(TRIM(I28),4))-VALUE(LEFT(TRIM(K28),4)))*12+VALUE(MID(TRIM(I28),6,2))-VALUE(MID(TRIM(K28),6,2)),"")) -> 4 | M28: =IF(TRIM(H28)="","",IFERROR(LOOKUP(2,1/(ISNUMBER(SEARCH('منطق دسته‌بندی'!$A$2:$A$187,H28))),'منطق دسته‌بندی'!$B$2:$B$187),"سایر (نیازمند بررسی دستی)")) -> خرابی - لامپ/LED داخلی (تعویض) | N28: MINI LED یخچال | O28: {=IF(A28="","",IF(SUMPRODUCT(($B$2:$B$965=B28)*($C$2:$C$965=C28)*($D$2:$D$965=D28)*($E$2:$E$965=E28)*($F$2:$F$965=F28)*($G$2:$G$965=G28)*($H$2:$H$965=H28)*($I$2:$I$965=I28)*($J$2:$J$965=J28)*($K$2:$K$965=K28)*($N$2:$N$965=N28))=1,"خیر",IF(SUMPRODUCT(($B$2:B28=B28)*($C$2:C28=C28)*($D$2:D28=D28)*($E$2:E28=E28)*($F$2:F28=F28)*($G$2:G28=G28)*($H$2:H28=H28)*($I$2:I28=I28)*($J$2:J28=J28)*($K$2:K28=K28)*($N$2:N28=N28))=1,"بله-1","بله")))} -> خیر | P28: {=IF(A28="","",IF(SUMPRODUCT(($F$2:$F$969=F28)*($I$2:$I$969=I28))=1,"خیر",IF(SUMPRODUCT(($F$2:F28=F28)*($I$2:I28=I28))=1,"بله-1","بله")))} -> خیر
A29: 210017169 | B29: مرداد | C29: 1405-05 | D29: یخچال مینی | E29: CM-RS5RE1 | F29: 52240003N00743 | G29: خاموش بودن LED کاور / سقفی — ایاب و ذهاب به عهده شرکت | H29: خرابی LED | I29: 1405/05/04 | J29: 1403/12/14 | K29: 1404/08/29 | L29: =IF(OR(TRIM(I29)="",TRIM(K29)=""),"",IFERROR((VALUE(LEFT(TRIM(I29),4))-VALUE(LEFT(TRIM(K29),4)))*12+VALUE(MID(TRIM(I29),6,2))-VALUE(MID(TRIM(K29),6,2)),"")) -> 9 | M29: =IF(TRIM(H29)="","",IFERROR(LOOKUP(2,1/(ISNUMBER(SEARCH('منطق دسته‌بندی'!$A$2:$A$187,H29))),'منطق دسته‌بندی'!$B$2:$B$187),"سایر (نیازمند بررسی دستی)")) -> خرابی - لامپ/LED داخلی (تعویض) | N29: MINI LED یخچال | O29: {=IF(A29="","",IF(SUMPRODUCT(($B$2:$B$965=B29)*($C$2:$C$965=C29)*($D$2:$D$965=D29)*($E$2:$E$965=E29)*($F$2:$F$965=F29)*($G$2:$G$965=G29)*($H$2:$H$965=H29)*($I$2:$I$965=I29)*($J$2:$J$965=J29)*($K$2:$K$965=K29)*($N$2:$N$965=N29))=1,"خیر",IF(SUMPRODUCT(($B$2:B29=B29)*($C$2:C29=C29)*($D$2:D29=D29)*($E$2:E29=E29)*($F$2:F29=F29)*($G$2:G29=G29)*($H$2:H29=H29)*($I$2:I29=I29)*($J$2:J29=J29)*($K$2:K29=K29)*($N$2:N29=N29))=1,"بله-1","بله")))} -> خیر | P29: {=IF(A29="","",IF(SUMPRODUCT(($F$2:$F$969=F29)*($I$2:$I$969=I29))=1,"خیر",IF(SUMPRODUCT(($F$2:F29=F29)*($I$2:I29=I29))=1,"بله-1","بله")))} -> خیر
A30: 210012249 | B30: فروردین | C30: 1405-01 | D30: یخچال مینی | E30: MINI-R (RE01) | F30: 52240003N00589 | G30: شکستگی قطعات تزئینی کابین- کد قطعه در لیست اقدامات درج می گردد. — ایاب و ذهاب به عهده شرکت | H30: شکستگی قطعات تزئینی داخل کابین - یخچال مینی | I30: 1405/01/24 | J30: 1403/10/24 | K30: 1404/10/08 | L30: =IF(OR(TRIM(I30)="",TRIM(K30)=""),"",IFERROR((VALUE(LEFT(TRIM(I30),4))-VALUE(LEFT(TRIM(K30),4)))*12+VALUE(MID(TRIM(I30),6,2))-VALUE(MID(TRIM(K30),6,2)),"")) -> 3 | M30: =IF(TRIM(H30)="","",IFERROR(LOOKUP(2,1/(ISNUMBER(SEARCH('منطق دسته‌بندی'!$A$2:$A$187,H30))),'منطق دسته‌بندی'!$B$2:$B$187),"سایر (نیازمند بررسی دستی)")) -> قطعات تزئینی - شکستگی/کسری (تعویض) | N30: قطعه تزئینی داخل کابین یخچال مینی | O30: {=IF(A30="","",IF(SUMPRODUCT(($B$2:$B$965=B30)*($C$2:$C$965=C30)*($D$2:$D$965=D30)*($E$2:$E$965=E30)*($F$2:$F$965=F30)*($G$2:$G$965=G30)*($H$2:$H$965=H30)*($I$2:$I$965=I30)*($J$2:$J$965=J30)*($K$2:$K$965=K30)*($N$2:$N$965=N30))=1,"خیر",IF(SUMPRODUCT(($B$2:B30=B30)*($C$2:C30=C30)*($D$2:D30=D30)*($E$2:E30=E30)*($F$2:F30=F30)*($G$2:G30=G30)*($H$2:H30=H30)*($I$2:I30=I30)*($J$2:J30=J30)*($K$2:K30=K30)*($N$2:N30=N30))=1,"بله-1","بله")))} -> خیر | P30: {=IF(A30="","",IF(SUMPRODUCT(($F$2:$F$969=F30)*($I$2:$I$969=I30))=1,"خیر",IF(SUMPRODUCT(($F$2:F30=F30)*($I$2:I30=I30))=1,"بله-1","بله")))} -> خیر
A31: 771166 | B31: اردیبهشت | C31: 1405-02 | D31: یخچال مینی | E31: MINI-R (RE01) | F31: 52240003N00558 | G31: گرم شدن محصول — ایاب و ذهاب به عهده شرکت | H31: تنظیم ترموستات | I31: 1405/02/12 | J31: 1403/10/23 | K31: 1405/01/22 | L31: =IF(OR(TRIM(I31)="",TRIM(K31)=""),"",IFERROR((VALUE(LEFT(TRIM(I31),4))-VALUE(LEFT(TRIM(K31),4)))*12+VALUE(MID(TRIM(I31),6,2))-VALUE(MID(TRIM(K31),6,2)),"")) -> 1 | M31: =IF(TRIM(H31)="","",IFERROR(LOOKUP(2,1/(ISNUMBER(SEARCH('منطق دسته‌بندی'!$A$2:$A$187,H31))),'منطق دسته‌بندی'!$B$2:$B$187),"سایر (نیازمند بررسی دستی)")) -> تنظیم ترموستات (تعمیر/تنظیم) | N31: ترموستات مینی | O31: {=IF(A31="","",IF(SUMPRODUCT(($B$2:$B$965=B31)*($C$2:$C$965=C31)*($D$2:$D$965=D31)*($E$2:$E$965=E31)*($F$2:$F$965=F31)*($G$2:$G$965=G31)*($H$2:$H$965=H31)*($I$2:$I$965=I31)*($J$2:$J$965=J31)*($K$2:$K$965=K31)*($N$2:$N$965=N31))=1,"خیر",IF(SUMPRODUCT(($B$2:B31=B31)*($C$2:C31=C31)*($D$2:D31=D31)*($E$2:E31=E31)*($F$2:F31=F31)*($G$2:G31=G31)*($H$2:H31=H31)*($I$2:I31=I31)*($J$2:J31=J31)*($K$2:K31=K31)*($N$2:N31=N31))=1,"بله-1","بله")))} -> خیر | P31: {=IF(A31="","",IF(SUMPRODUCT(($F$2:$F$969=F31)*($I$2:$I$969=I31))=1,"خیر",IF(SUMPRODUCT(($F$2:F31=F31)*($I$2:I31=I31))=1,"بله-1","بله")))} -> خیر
A32: 210018186 | B32: مرداد | C32: 1405-05 | D32: یخچال مینی | E32: MINI-R (RE01) | F32: 52240003N00529 | G32: خاموش بودن LED کاور / سقفی — ایاب و ذهاب به عهده مشتری | H32: خرابی LED | I32: 1405/05/10 | J32: 1403/10/22 | K32: 1404/01/26 | L32: =IF(OR(TRIM(I32)="",TRIM(K32)=""),"",IFERROR((VALUE(LEFT(TRIM(I32),4))-VALUE(LEFT(TRIM(K32),4)))*12+VALUE(MID(TRIM(I32),6,2))-VALUE(MID(TRIM(K32),6,2)),"")) -> 16 | M32: =IF(TRIM(H32)="","",IFERROR(LOOKUP(2,1/(ISNUMBER(SEARCH('منطق دسته‌بندی'!$A$2:$A$187,H32))),'منطق دسته‌بندی'!$B$2:$B$187),"سایر (نیازمند بررسی دستی)")) -> خرابی - لامپ/LED داخلی (تعویض) | N32: MINI LED یخچال | O32: {=IF(A32="","",IF(SUMPRODUCT(($B$2:$B$965=B32)*($C$2:$C$965=C32)*($D$2:$D$965=D32)*($E$2:$E$965=E32)*($F$2:$F$965=F32)*($G$2:$G$965=G32)*($H$2:$H$965=H32)*($I$2:$I$965=I32)*($J$2:$J$965=J32)*($K$2:$K$965=K32)*($N$2:$N$965=N32))=1,"خیر",IF(SUMPRODUCT(($B$2:B32=B32)*($C$2:C32=C32)*($D$2:D32=D32)*($E$2:E32=E32)*($F$2:F32=F32)*($G$2:G32=G32)*($H$2:H32=H32)*($I$2:I32=I32)*($J$2:J32=J32)*($K$2:K32=K32)*($N$2:N32=N32))=1,"بله-1","بله")))} -> خیر | P32: {=IF(A32="","",IF(SUMPRODUCT(($F$2:$F$969=F32)*($I$2:$I$969=I32))=1,"خیر",IF(SUMPRODUCT(($F$2:F32=F32)*($I$2:I32=I32))=1,"بله-1","بله")))} -> خیر
A33: 210009179 | B33: اردیبهشت | C33: 1405-02 | D33: یخچال مینی | E33: CM-RS5BK1 | F33: 52240002N01230 | G33: خاموش بودن LED کاور / سقفی — ایاب و ذهاب به عهده شرکت | H33: خرابی LED | I33: 1405/02/15 | J33: 1404/05/22 | K33: 1404/08/10 | L33: =IF(OR(TRIM(I33)="",TRIM(K33)=""),"",IFERROR((VALUE(LEFT(TRIM(I33),4))-VALUE(LEFT(TRIM(K33),4)))*12+VALUE(MID(TRIM(I33),6,2))-VALUE(MID(TRIM(K33),6,2)),"")) -> 6 | M33: =IF(TRIM(H33)="","",IFERROR(LOOKUP(2,1/(ISNUMBER(SEARCH('منطق دسته‌بندی'!$A$2:$A$187,H33))),'منطق دسته‌بندی'!$B$2:$B$187),"سایر (نیازمند بررسی دستی)")) -> خرابی - لامپ/LED داخلی (تعویض) | N33: لامپ مینی | O33: {=IF(A33="","",IF(SUMPRODUCT(($B$2:$B$965=B33)*($C$2:$C$965=C33)*($D$2:$D$965=D33)*($E$2:$E$965=E33)*($F$2:$F$965=F33)*($G$2:$G$965=G33)*($H$2:$H$965=H33)*($I$2:$I$965=I33)*($J$2:$J$965=J33)*($K$2:$K$965=K33)*($N$2:$N$965=N33))=1,"خیر",IF(SUMPRODUCT(($B$2:B33=B33)*($C$2:C33=C33)*($D$2:D33=D33)*($E$2:E33=E33)*($F$2:F33=F33)*($G$2:G33=G33)*($H$2:H33=H33)*($I$2:I33=I33)*($J$2:J33=J33)*($K$2:K33=K33)*($N$2:N33=N33))=1,"بله-1","بله")))} -> خیر | P33: {=IF(A33="","",IF(SUMPRODUCT(($F$2:$F$969=F33)*($I$2:$I$969=I33))=1,"خیر",IF(SUMPRODUCT(($F$2:F33=F33)*($I$2:I33=I33))=1,"بله-1","بله")))} -> خیر
A34: 210014173 | B34: خرداد | C34: 1405-03 | D34: یخچال مینی | E34: CM-RS5BK1 | F34: 52240002N01230 | G34: خاموش و روشن شدن LED کاور / سقفی — مجدد — ایاب و ذهاب به عهده شرکت | H34: خرابی ال ای دی داخل کابین - یخچال مینی | I34: 1405/03/10 | J34: 1404/05/22 | K34: 1404/08/10 | L34: =IF(OR(TRIM(I34)="",TRIM(K34)=""),"",IFERROR((VALUE(LEFT(TRIM(I34),4))-VALUE(LEFT(TRIM(K34),4)))*12+VALUE(MID(TRIM(I34),6,2))-VALUE(MID(TRIM(K34),6,2)),"")) -> 7 | M34: =IF(TRIM(H34)="","",IFERROR(LOOKUP(2,1/(ISNUMBER(SEARCH('منطق دسته‌بندی'!$A$2:$A$187,H34))),'منطق دسته‌بندی'!$B$2:$B$187),"سایر (نیازمند بررسی دستی)")) -> خرابی - لامپ/LED داخلی (تعویض) | N34: لامپ مینی | O34: {=IF(A34="","",IF(SUMPRODUCT(($B$2:$B$965=B34)*($C$2:$C$965=C34)*($D$2:$D$965=D34)*($E$2:$E$965=E34)*($F$2:$F$965=F34)*($G$2:$G$965=G34)*($H$2:$H$965=H34)*($I$2:$I$965=I34)*($J$2:$J$965=J34)*($K$2:$K$965=K34)*($N$2:$N$965=N34))=1,"خیر",IF(SUMPRODUCT(($B$2:B34=B34)*($C$2:C34=C34)*($D$2:D34=D34)*($E$2:E34=E34)*($F$2:F34=F34)*($G$2:G34=G34)*($H$2:H34=H34)*($I$2:I34=I34)*($J$2:J34=J34)*($K$2:K34=K34)*($N$2:N34=N34))=1,"بله-1","بله")))} -> خیر | P34: {=IF(A34="","",IF(SUMPRODUCT(($F$2:$F$969=F34)*($I$2:$I$969=I34))=1,"خیر",IF(SUMPRODUCT(($F$2:F34=F34)*($I$2:I34=I34))=1,"بله-1","بله")))} -> خیر
A35: 210005449 | B35: فروردین | C35: 1405-01 | D35: یخچال مینی | E35: CM-RS5BK1 | F35: 52240002N01230 | G35: ایاب و ذهاب به عهده شرکت خاموش بودن LED کاور / سقفی | H35: خرابی ال ای دی داخل کابین - یخچال مینی | I35: 1405/01/29 | J35: 1404/05/22 | K35: 1404/08/10 | L35: =IF(OR(TRIM(I35)="",TRIM(K35)=""),"",IFERROR((VALUE(LEFT(TRIM(I35),4))-VALUE(LEFT(TRIM(K35),4)))*12+VALUE(MID(TRIM(I35),6,2))-VALUE(MID(TRIM(K35),6,2)),"")) -> 5 | M35: =IF(TRIM(H35)="","",IFERROR(LOOKUP(2,1/(ISNUMBER(SEARCH('منطق دسته‌بندی'!$A$2:$A$187,H35))),'منطق دسته‌بندی'!$B$2:$B$187),"سایر (نیازمند بررسی دستی)")) -> خرابی - لامپ/LED داخلی (تعویض) | N35: لامپ مینی | O35: {=IF(A35="","",IF(SUMPRODUCT(($B$2:$B$965=B35)*($C$2:$C$965=C35)*($D$2:$D$965=D35)*($E$2:$E$965=E35)*($F$2:$F$965=F35)*($G$2:$G$965=G35)*($H$2:$H$965=H35)*($I$2:$I$965=I35)*($J$2:$J$965=J35)*($K$2:$K$965=K35)*($N$2:$N$965=N35))=1,"خیر",IF(SUMPRODUCT(($B$2:B35=B35)*($C$2:C35=C35)*($D$2:D35=D35)*($E$2:E35=E35)*($F$2:F35=F35)*($G$2:G35=G35)*($H$2:H35=H35)*($I$2:I35=I35)*($J$2:J35=J35)*($K$2:K35=K35)*($N$2:N35=N35))=1,"بله-1","بله")))} -> خیر | P35: {=IF(A35="","",IF(SUMPRODUCT(($F$2:$F$969=F35)*($I$2:$I$969=I35))=1,"خیر",IF(SUMPRODUCT(($F$2:F35=F35)*($I$2:I35=I35))=1,"بله-1","بله")))} -> خیر
A36: 510024651 | B36: مرداد | C36: 1405-05 | D36: یخچال مینی | E36: CM-RS5BK1 | F36: 52240002N01029 | G36: خاموش بودن LED کاور / سقفي**اياب و ذهاب به عهده شرکت | H36: خرابی LED | I36: 1405/05/31 | J36: 1403/12/22 | K36: 1404/06/17 | L36: =IF(OR(TRIM(I36)="",TRIM(K36)=""),"",IFERROR((VALUE(LEFT(TRIM(I36),4))-VALUE(LEFT(TRIM(K36),4)))*12+VALUE(MID(TRIM(I36),6,2))-VALUE(MID(TRIM(K36),6,2)),"")) -> 11 | M36: =IF(TRIM(H36)="","",IFERROR(LOOKUP(2,1/(ISNUMBER(SEARCH('منطق دسته‌بندی'!$A$2:$A$187,H36))),'منطق دسته‌بندی'!$B$2:$B$187),"سایر (نیازمند بررسی دستی)")) -> خرابی - لامپ/LED داخلی (تعویض) | N36: MINI LED یخچال | O36: {=IF(A36="","",IF(SUMPRODUCT(($B$2:$B$965=B36)*($C$2:$C$965=C36)*($D$2:$D$965=D36)*($E$2:$E$965=E36)*($F$2:$F$965=F36)*($G$2:$G$965=G36)*($H$2:$H$965=H36)*($I$2:$I$965=I36)*($J$2:$J$965=J36)*($K$2:$K$965=K36)*($N$2:$N$965=N36))=1,"خیر",IF(SUMPRODUCT(($B$2:B36=B36)*($C$2:C36=C36)*($D$2:D36=D36)*($E$2:E36=E36)*($F$2:F36=F36)*($G$2:G36=G36)*($H$2:H36=H36)*($I$2:I36=I36)*($J$2:J36=J36)*($K$2:K36=K36)*($N$2:N36=N36))=1,"بله-1","بله")))} -> خیر | P36: {=IF(A36="","",IF(SUMPRODUCT(($F$2:$F$969=F36)*($I$2:$I$969=I36))=1,"خیر",IF(SUMPRODUCT(($F$2:F36=F36)*($I$2:I36=I36))=1,"بله-1","بله")))} -> خیر
A37: 210018851 | B37: مرداد | C37: 1405-05 | D37: یخچال مینی | E37: CM-RS5BK1 | F37: 52240002N00908 | G37: گرم شدن محصول — ایاب و ذهاب به عهده شرکت | H37: خرابی کمپرسور | I37: 1405/05/15 | J37: 1403/12/13 | K37: 1404/09/09 | L37: =IF(OR(TRIM(I37)="",TRIM(K37)=""),"",IFERROR((VALUE(LEFT(TRIM(I37),4))-VALUE(LEFT(TRIM(K37),4)))*12+VALUE(MID(TRIM(I37),6,2))-VALUE(MID(TRIM(K37),6,2)),"")) -> 8 | M37: =IF(TRIM(H37)="","",IFERROR(LOOKUP(2,1/(ISNUMBER(SEARCH('منطق دسته‌بندی'!$A$2:$A$187,H37))),'منطق دسته‌بندی'!$B$2:$B$187),"سایر (نیازمند بررسی دستی)")) -> خرابی - کمپرسور (تعویض) | N37: کمپرسور EMX26 MINI | O37: {=IF(A37="","",IF(SUMPRODUCT(($B$2:$B$965=B37)*($C$2:$C$965=C37)*($D$2:$D$965=D37)*($E$2:$E$965=E37)*($F$2:$F$965=F37)*($G$2:$G$965=G37)*($H$2:$H$965=H37)*($I$2:$I$965=I37)*($J$2:$J$965=J37)*($K$2:$K$965=K37)*($N$2:$N$965=N37))=1,"خیر",IF(SUMPRODUCT(($B$2:B37=B37)*($C$2:C37=C37)*($D$2:D37=D37)*($E$2:E37=E37)*($F$2:F37=F37)*($G$2:G37=G37)*($H$2:H37=H37)*($I$2:I37=I37)*($J$2:J37=J37)*($K$2:K37=K37)*($N$2:N37=N37))=1,"بله-1","بله")))} -> خیر | P37: {=IF(A37="","",IF(SUMPRODUCT(($F$2:$F$969=F37)*($I$2:$I$969=I37))=1,"خیر",IF(SUMPRODUCT(($F$2:F37=F37)*($I$2:I37=I37))=1,"بله-1","بله")))} -> خیر
A38: 210023908 | B38: شهریور | C38: 1405-06 | D38: یخچال مینی | E38: CM-RS5BK1 | F38: 52240002N00847 | G38: از کار افتادن محصول**اياب و ذهاب به عهده شرکت | H38: خرابی کلید فشاری | I38: 1405/06/16 | J38: 1403/12/10 | K38: 1405/04/15 | L38: =IF(OR(TRIM(I38)="",TRIM(K38)=""),"",IFERROR((VALUE(LEFT(TRIM(I38),4))-VALUE(LEFT(TRIM(K38),4)))*12+VALUE(MID(TRIM(I38),6,2))-VALUE(MID(TRIM(K38),6,2)),"")) -> 2 | M38: =IF(TRIM(H38)="","",IFERROR(LOOKUP(2,1/(ISNUMBER(SEARCH('منطق دسته‌بندی'!$A$2:$A$187,H38))),'منطق دسته‌بندی'!$B$2:$B$187),"سایر (نیازمند بررسی دستی)")) -> کلید فشاری (تعویض/بازبینی) | N38: MINI کليد فشاري يخچال | O38: {=IF(A38="","",IF(SUMPRODUCT(($B$2:$B$965=B38)*($C$2:$C$965=C38)*($D$2:$D$965=D38)*($E$2:$E$965=E38)*($F$2:$F$965=F38)*($G$2:$G$965=G38)*($H$2:$H$965=H38)*($I$2:$I$965=I38)*($J$2:$J$965=J38)*($K$2:$K$965=K38)*($N$2:$N$965=N38))=1,"خیر",IF(SUMPRODUCT(($B$2:B38=B38)*($C$2:C38=C38)*($D$2:D38=D38)*($E$2:E38=E38)*($F$2:F38=F38)*($G$2:G38=G38)*($H$2:H38=H38)*($I$2:I38=I38)*($J$2:J38=J38)*($K$2:K38=K38)*($N$2:N38=N38))=1,"بله-1","بله")))} -> خیر | P38: {=IF(A38="","",IF(SUMPRODUCT(($F$2:$F$969=F38)*($I$2:$I$969=I38))=1,"خیر",IF(SUMPRODUCT(($F$2:F38=F38)*($I$2:I38=I38))=1,"بله-1","بله")))} -> خیر
A39: 770306 | B39: اردیبهشت | C39: 1405-02 | D39: یخچال مینی | E39: CM-RS5BK1 | F39: 52240002N00838 | G39: گرم شدن محصول ایاب و ذهاب به عهده شرکت | H39: نشتی گاز - نامشخص - یخچال مینی | I39: 1405/02/08 | J39: 1403/12/11 | K39: 1404/05/28 | L39: =IF(OR(TRIM(I39)="",TRIM(K39)=""),"",IFERROR((VALUE(LEFT(TRIM(I39),4))-VALUE(LEFT(TRIM(K39),4)))*12+VALUE(MID(TRIM(I39),6,2))-VALUE(MID(TRIM(K39),6,2)),"")) -> 9 | M39: =IF(TRIM(H39)="","",IFERROR(LOOKUP(2,1/(ISNUMBER(SEARCH('منطق دسته‌بندی'!$A$2:$A$187,H39))),'منطق دسته‌بندی'!$B$2:$B$187),"سایر (نیازمند بررسی دستی)")) -> نشتی آب - محل نامشخص (نیازمند بازدید) | N39: — | O39: {=IF(A39="","",IF(SUMPRODUCT(($B$2:$B$965=B39)*($C$2:$C$965=C39)*($D$2:$D$965=D39)*($E$2:$E$965=E39)*($F$2:$F$965=F39)*($G$2:$G$965=G39)*($H$2:$H$965=H39)*($I$2:$I$965=I39)*($J$2:$J$965=J39)*($K$2:$K$965=K39)*($N$2:$N$965=N39))=1,"خیر",IF(SUMPRODUCT(($B$2:B39=B39)*($C$2:C39=C39)*($D$2:D39=D39)*($E$2:E39=E39)*($F$2:F39=F39)*($G$2:G39=G39)*($H$2:H39=H39)*($I$2:I39=I39)*($J$2:J39=J39)*($K$2:K39=K39)*($N$2:N39=N39))=1,"بله-1","بله")))} -> خیر | P39: {=IF(A39="","",IF(SUMPRODUCT(($F$2:$F$969=F39)*($I$2:$I$969=I39))=1,"خیر",IF(SUMPRODUCT(($F$2:F39=F39)*($I$2:I39=I39))=1,"بله-1","بله")))} -> خیر
A40: 210012002 | B40: فروردین | C40: 1405-01 | D40: یخچال مینی | E40: CM-RS5BK1 | F40: 52240002N00838 | G40: گرم شدن محصول — ایاب و ذهاب به عهده شرکت | H40: خرابی ترموستات - یخچال مینی | I40: 1405/01/22 | J40: 1403/12/11 | K40: 1404/05/28 | L40: =IF(OR(TRIM(I40)="",TRIM(K40)=""),"",IFERROR((VALUE(LEFT(TRIM(I40),4))-VALUE(LEFT(TRIM(K40),4)))*12+VALUE(MID(TRIM(I40),6,2))-VALUE(MID(TRIM(K40),6,2)),"")) -> 8 | M40: =IF(TRIM(H40)="","",IFERROR(LOOKUP(2,1/(ISNUMBER(SEARCH('منطق دسته‌بندی'!$A$2:$A$187,H40))),'منطق دسته‌بندی'!$B$2:$B$187),"سایر (نیازمند بررسی دستی)")) -> خرابی - ترموستات/سنسور دما (تعویض) | N40: ترموستات مینی | O40: {=IF(A40="","",IF(SUMPRODUCT(($B$2:$B$965=B40)*($C$2:$C$965=C40)*($D$2:$D$965=D40)*($E$2:$E$965=E40)*($F$2:$F$965=F40)*($G$2:$G$965=G40)*($H$2:$H$965=H40)*($I$2:$I$965=I40)*($J$2:$J$965=J40)*($K$2:$K$965=K40)*($N$2:$N$965=N40))=1,"خیر",IF(SUMPRODUCT(($B$2:B40=B40)*($C$2:C40=C40)*($D$2:D40=D40)*($E$2:E40=E40)*($F$2:F40=F40)*($G$2:G40=G40)*($H$2:H40=H40)*($I$2:I40=I40)*($J$2:J40=J40)*($K$2:K40=K40)*($N$2:N40=N40))=1,"بله-1","بله")))} -> خیر | P40: {=IF(A40="","",IF(SUMPRODUCT(($F$2:$F$969=F40)*($I$2:$I$969=I40))=1,"خیر",IF(SUMPRODUCT(($F$2:F40=F40)*($I$2:I40=I40))=1,"بله-1","بله")))} -> خیر
...

Sheet منطق دسته‌بندی
A1: کلیدواژه / عبارت | B1: دسته علت خرابی | C1: اولویت
A2: برد نمایشگر | B2: خرابی - برد نمایش/مین برد (تعویض) | C2: 1
A3: مین برد | B3: خرابی - برد نمایش/مین برد (تعویض) | C3: 1
A4: مين برد | B4: خرابی - برد نمایش/مین برد (تعویض) | C4: 1
A5: برد | B5: خرابی - برد الکترونیک (تعویض) | C5: 1
A6: دیسپلی | B6: خرابی - برد الکترونیک (تعویض) | C6: 1
A7: ديسپل | B7: خرابی - برد الکترونیک (تعویض) | C7: 1
A8: ریموت | B8: ریموت کنترل (تعویض/تعمیر) | C8: 1
A9: ريموت | B9: ریموت کنترل (تعویض/تعمیر) | C9: 1
A10: LED | B10: خرابی - لامپ/LED داخلی (تعویض) | C10: 1
A11: ال ای دی | B11: خرابی - لامپ/LED داخلی (تعویض) | C11: 1
A12: ال اي دي | B12: خرابی - لامپ/LED داخلی (تعویض) | C12: 1
A13: زنگ زدگی | B13: زنگ‌زدگی بدنه/قطعه (تعویض) | C13: 1
... A187: تنظیم ترموستات | B187: تنظیم ترموستات (تعمیر/تنظیم) | C187: 9
